<?xml version="1.0" ?>
<robot name="ant"  xmlns:xacro="http://www.ros.org/wiki/xacro">

  <xacro:property name="j_eff" value="5" />
  <xacro:property name="j_vel" value="5" />

  <!-- thorax to cox -->
  <xacro:property name="f_l_1_low" value="-0.4" />
  <xacro:property name="f_l_1_upp" value="0.6" />
  <xacro:property name="f_r_1_low" value="-0.6" />
  <xacro:property name="f_r_1_upp" value="0.4" />

  <xacro:property name="m_l_1_low" value="-0.65" />
  <xacro:property name="m_l_1_upp" value="0.15" />
  <xacro:property name="m_r_1_low" value="-0.15" />
  <xacro:property name="m_r_1_upp" value="0.65" />

  <xacro:property name="r_l_1_low" value="-0.4" />
  <xacro:property name="r_l_1_upp" value="0.25" />
  <xacro:property name="r_r_1_low" value="-0.25" />
  <xacro:property name="r_r_1_upp" value="0.4" /> 

  <!-- cox to trochanter -->
  <xacro:property name="f_l_2_low" value="-0.3" />
  <xacro:property name="f_l_2_upp" value="0.5" />
  <xacro:property name="f_r_2_low" value="-0.5" />
  <xacro:property name="f_r_2_upp" value="0.3" />

  <xacro:property name="m_l_2_low" value="-0.13" />
  <xacro:property name="m_l_2_upp" value="0.5" />
  <xacro:property name="m_r_2_low" value="-0.5" />
  <xacro:property name="m_r_2_upp" value="0.13" />

  <xacro:property name="r_l_2_low" value="-0.15" />
  <xacro:property name="r_l_2_upp" value="0.5" />
  <xacro:property name="r_r_2_low" value="-0.5" />
  <xacro:property name="r_r_2_upp" value="0.15" /> 

  <!-- femur to tibia -->
  <xacro:property name="f_lr_3_low" value="0" />
  <xacro:property name="f_lr_3_upp" value="0.72" />

  <xacro:property name="m_lr_3_low" value="0" />
  <xacro:property name="m_lr_3_upp" value="0.4" />

  <xacro:property name="r_lr_3_low" value="0" />
  <xacro:property name="r_lr_3_upp" value="0.4" />


  <!-- rviz wont work with these xacros unless given as urdf

  <xacro:include filename="$(find ant_description)/urdf/ant_main_body.xacro"/>

  <xacro:include filename="$(find ant_description)/urdf/ant_leg_l_f.xacro" />

  <xacro:include filename="$(find ant_description)/urdf/ant_leg_r_f.xacro" /> -->

  <link name="base_link"/>

  <joint name="ant_attachment" type="fixed">
    <parent link="base_link"/>
    <child link="thorax"/>
    <origin xyz="0 0 0" rpy="0 0 0"/>
  </joint>

  <!-- thorax link -->
  <link name="thorax">
    <collision>
      <origin xyz="0.02495771 4.745264 0.9420236" rpy="0 0 0"/>
      <geometry>
        <mesh filename="package://ant_description/meshes/thorax.dae"/>
      </geometry>
    </collision>

    <visual>
      <origin xyz="0.02495771 4.745264 0.9420236" rpy="0 0 0"/>
      <geometry>
        <mesh filename="package://ant_description/meshes/thorax.dae"/>
      </geometry>
    </visual>

    <inertial>
      <origin xyz="-0.04847949 5.0895386 1.30014761" rpy="0 0 0"/>
      <mass value="3.9e-03"/>
      <inertia
        ixx="2.1035494417e-02" 
        ixy="-1.5113838359e-05" 
        ixz="-4.2300683022e-06"
        iyy="5.1998491717e-03" 
        iyz="-1.7132421990e-03"
        izz="2.1783020009e-02"/>
    </inertial>
  </link> 

  <!-- head link -->
  <link name="head">
    <collision>
      <origin xyz="8.69815e-4 11.79549 -0.03817248" rpy="0 0 0"/>
      <geometry>
        <mesh filename="package://ant_description/meshes/head.dae"/>
      </geometry>
    </collision>

    <visual>
      <origin xyz="8.69815e-4 11.79549 -0.03817248" rpy="0 0 0"/>
      <geometry>
        <mesh filename="package://ant_description/meshes/head.dae"/>
      </geometry>
    </visual>

    <inertial>
      <origin xyz="0.001631625 11.33051132 0.00357429" rpy="0 0 0"/> 
      <mass value="4.9e-03"/>
      <inertia
        ixx="1.0024249488e-02" 
        ixy="-3.9557829295e-05" 
        ixz="-4.4694485573e-08"
        iyy="1.0396055307e-02" 
        iyz="1.1638522655e-03"
        izz="1.3252518268e-02"/>
    </inertial>
  </link>

  <joint name="thorax_head" type="fixed">
    <parent link="thorax"/>
    <child link="head"/>
  </joint> 

  <!-- eye left link -->
  <link name="eye_l">
    <collision>
      <origin xyz="-2.086435 11.59313 0.2650509" rpy="0 0 0"/>
      <geometry>
        <mesh filename="package://ant_description/meshes/eye_l.dae"/>
      </geometry>
    </collision>

    <visual>
      <origin xyz="-2.086435 11.59313 0.2650509" rpy="0 0 0"/>
      <geometry>
        <mesh filename="package://ant_description/meshes/eye_l.dae"/>
      </geometry>
    </visual>

    <inertial>
      <origin xyz="-2.09985028 11.5658733 0.2633888" rpy="0 0 0"/> 
      <mass value="0.01e-03"/>
      <inertia
        ixx="8.1670536945e-07" 
        ixy="-1.0827793204e-07" 
        ixz="-6.1851114941e-08"
        iyy="4.3301748852e-07" 
        iyz="1.0580506602e-07"
        izz="5.3558668918e-07"/>
    </inertial>
  </link>  

  <joint name="head_eye_l" type="fixed">
    <parent link="head"/>
    <child link="eye_l"/>
  </joint> 

  <!-- eye right link -->
  <link name="eye_r">
    <collision>
      <origin xyz="2.086435 11.59313 0.2650509" rpy="0 0 0"/>
      <geometry>
        <mesh filename="package://ant_description/meshes/eye_r.dae"/>
      </geometry>
    </collision>

    <visual>
      <origin xyz="2.086435 11.59313 0.2650509" rpy="0 0 0"/>
      <geometry>
        <mesh filename="package://ant_description/meshes/eye_r.dae"/>
      </geometry>
    </visual>

    <inertial>
      <origin xyz="2.09985028 11.5658733 0.2633888" rpy="0 0 0"/> 
      <mass value="0.01e-03"/>
      <inertia
        ixx="8.1670536945e-07" 
        ixy="1.0827793204e-07" 
        ixz="6.1851114941e-08"
        iyy="4.3301748852e-07" 
        iyz="1.0580506602e-07"
        izz="5.3558668918e-07"/>
    </inertial>
  </link>  

  <joint name="head_eye_r" type="fixed">
    <parent link="head"/>
    <child link="eye_r"/>
  </joint>  

  <!-- mandible left link -->
  <link name="mandible_l">
    <collision>
      <origin xyz="-0.7011991 14.09823 -1.611525" rpy="0 0 0"/>
      <geometry>
        <mesh filename="package://ant_description/meshes/mandible_l.dae"/>
      </geometry>
    </collision>

    <visual>
      <origin xyz="-0.7011991 14.09823 -1.611525" rpy="0 0 0"/>
      <geometry>
        <mesh filename="package://ant_description/meshes/mandible_l.dae"/>
      </geometry>
    </visual>

    <inertial>
      <origin xyz="-0.86942116 13.87568539 -1.37582832" rpy="0 0 0"/> 
      <mass value="0.05e-03"/>
      <inertia
        ixx="1.9614048448e-05" 
        ixy="-3.6497548646e-06" 
        ixz="1.9188628202e-06"
        iyy="8.5626312372e-06" 
        iyz="6.0437642398e-06"
        izz="1.7499035225e-05"/>
    </inertial>
  </link>  

  <joint name="head_mandible_l" type="fixed">
    <parent link="head"/>
    <child link="mandible_l"/>
  </joint> 

  <!-- mandible right link -->
  <link name="mandible_r">
    <collision>
      <origin xyz="0.6943221 14.09485 -1.611031" rpy="0 0 0"/>
      <geometry>
        <mesh filename="package://ant_description/meshes/mandible_r.dae"/>
      </geometry>
    </collision>

    <visual>
      <origin xyz="0.6943221 14.09485 -1.611031" rpy="0 0 0"/>
      <geometry>
        <mesh filename="package://ant_description/meshes/mandible_r.dae"/>
      </geometry>
    </visual>

    <inertial>
      <origin xyz="0.86872115 13.88107856 -1.37675615" rpy="0 0 0"/> 
      <mass value="0.05e-03"/>
      <inertia
        ixx="1.9699720301e-05" 
        ixy="3.6657541619e-06" 
        ixz="-1.9418835815e-06"
        iyy="8.5999130502e-06" 
        iyz="6.0833641747e-06"
        izz="1.7563072740e-05"/>
    </inertial>
  </link>  

  <joint name="head_mandible_r" type="fixed">
    <parent link="head"/>
    <child link="mandible_r"/>
  </joint> 

  <!-- scape left link -->
  <link name="scape_l">
    <collision>
      <origin xyz="-0.7057881 12.91887 2.897474" rpy="0 0 0"/>
      <geometry>
        <mesh filename="package://ant_description/meshes/scape_l.dae"/>
      </geometry>
    </collision>

    <visual>
      <origin xyz="-0.7057881 12.91887 2.897474" rpy="0 0 0"/>
      <geometry>
        <mesh filename="package://ant_description/meshes/scape_l.dae"/>
      </geometry>
    </visual>

    <inertial>
      <origin xyz="-0.6883985 12.92029373 3.50715658" rpy="0 0 0"/> 
      <mass value="0.05e-03"/>
      <inertia
        ixx="1.2802315519e-04" 
        ixy="3.2000491723e-09" 
        ixz="1.6031652630e-06"
        iyy="1.2802344276e-04" 
        iyz="-9.2018642038e-07"
        izz="6.3649765718e-07"/>
    </inertial>
  </link>  

  <joint name="head_scape_l" type="fixed">
    <parent link="head"/>
    <child link="scape_l"/>
  </joint> 

  <!-- scape right link -->
  <link name="scape_r">
    <collision>
      <origin xyz="0.7057881 12.91887 2.897474" rpy="0 0 0"/>
      <geometry>
        <mesh filename="package://ant_description/meshes/scape_r.dae"/>
      </geometry>
    </collision>

    <visual>
      <origin xyz="0.7057881 12.91887 2.897474" rpy="0 0 0"/>
      <geometry>
        <mesh filename="package://ant_description/meshes/scape_r.dae"/>
      </geometry>
    </visual>

    <inertial>
      <origin xyz="0.6883985 12.92029373 3.50715658" rpy="0 0 0"/> 
      <mass value="0.05e-03"/>
      <inertia
        ixx="1.2802315519e-04" 
        ixy="-3.2000491723e-09" 
        ixz="-1.6031652630e-06"
        iyy="1.2802344276e-04" 
        iyz="-9.2018642038e-07"
        izz="6.3649765718e-07"/>
    </inertial>
  </link>  

  <joint name="head_scape_r" type="fixed">
    <parent link="head"/>
    <child link="scape_r"/>
  </joint> 

  <!-- flagellum left link -->
  <link name="flagellum_l">
    <collision>
      <origin xyz="-1.797092 16.61842 6.703302" rpy="0 0 0"/>
      <geometry>
        <mesh filename="package://ant_description/meshes/flagellum_l.dae"/>
      </geometry>
    </collision>

    <visual>
      <origin xyz="-1.797092 16.61842 6.703302" rpy="0 0 0"/>
      <geometry>
        <mesh filename="package://ant_description/meshes/flagellum_l.dae"/>
      </geometry>
    </visual>

    <inertial>
      <origin xyz="-2.20728987 17.81900304 6.88739471" rpy="0 0 0"/> 
      <mass value="0.05e-03"/>
      <inertia
        ixx="1.7112108081e-04" 
        ixy="5.9288246827e-05" 
        ixz="8.0065632101e-06"
        iyy="2.7674746548e-05" 
        iyz="-2.3324145091e-05"
        izz="1.8891776610e-04"/>
    </inertial>
  </link>  

  <joint name="scape_flagellum_l" type="fixed">
    <parent link="scape_l"/>
    <child link="flagellum_l"/>
  </joint> 

  <!-- flagellum right link -->
  <link name="flagellum_r">
    <collision>
      <origin xyz="1.797092 16.61842 6.703302" rpy="0 0 0"/>
      <geometry>
        <mesh filename="package://ant_description/meshes/flagellum_r.dae"/>
      </geometry>
    </collision>

    <visual>
      <origin xyz="1.797092 16.61842 6.703302" rpy="0 0 0"/>
      <geometry>
        <mesh filename="package://ant_description/meshes/flagellum_r.dae"/>
      </geometry>
    </visual>

    <inertial>
      <origin xyz="2.20728987 17.81900304 6.88739471" rpy="0 0 0"/> 
      <mass value="0.05e-03"/>
      <inertia
        ixx="1.7112108081e-04" 
        ixy="-5.9288246827e-05" 
        ixz="-8.0065632101e-06"
        iyy="2.7674746548e-05" 
        iyz="-2.3324145091e-05"
        izz="1.8891776610e-04"/>
    </inertial>
  </link>  

  <joint name="scape_flagellum_r" type="fixed">
    <parent link="scape_r"/>
    <child link="flagellum_r"/>
  </joint>

  <!-- petiole link -->
  <link name="petiole">
    <collision>
      <origin xyz="0.01740854 0.07322531 0.2697668" rpy="0 0 0"/>
      <geometry>
        <mesh filename="package://ant_description/meshes/petiole.dae"/>
      </geometry>
    </collision>

    <visual>
      <origin xyz="0.01740854 0.07322531 0.2697668" rpy="0 0 0"/>
      <geometry>
        <mesh filename="package://ant_description/meshes/petiole.dae"/>
      </geometry>
    </visual>

    <inertial>
      <origin xyz="0.00561879 0.00296973 0.28649062" rpy="0 0 0"/> 
      <mass value="0.4e-03"/>
      <inertia
        ixx="2.2318367969e-04" 
        ixy="2.8626159873e-07" 
        ixz="-2.5921425202e-07"
        iyy="2.0440317885e-04" 
        iyz="-3.2069241778e-05"
        izz="1.6371935771e-04"/>
    </inertial>
  </link>  
  
  <joint name="thorax_petiole" type="fixed">
    <parent link="thorax"/>
    <child link="petiole"/>
  </joint> 

  <!-- node link --> 
  <link name="node">
    <collision>
      <origin xyz="-0.006898105 -1.105468 -0.2202131" rpy="0 0 0"/>
      <geometry>
        <mesh filename="package://ant_description/meshes/node.dae"/>
      </geometry>
    </collision>

    <visual>
      <origin xyz="-0.006898105 -1.105468 -0.2202131" rpy="0 0 0"/>
      <geometry>
        <mesh filename="package://ant_description/meshes/node.dae"/>
      </geometry>
    </visual>

    <inertial>
      <origin xyz="-0.011776415 -1.10854547 -0.22971905" rpy="0 0 0"/> 
      <mass value="0.4e-03"/>
      <inertia
        ixx="7.0917257902e-05" 
        ixy="-9.3617110600e-08" 
        ixz="4.5183317475e-07"
        iyy="4.2925665045e-05" 
        iyz="-1.2714177689e-07"
        izz="7.6850739070e-05"/>
    </inertial>
  </link>  

  <joint name="petiole_node" type="fixed">
    <parent link="petiole"/>
    <child link="node"/>
  </joint> 

  <!-- gaster link --> 
  <link name="gaster">
    <collision>
      <origin xyz="-0.003080308 -4.342331 -1.633749" rpy="0 0 0"/>
      <geometry>
        <mesh filename="package://ant_description/meshes/gaster.dae"/>
      </geometry>
    </collision>

    <visual>
      <origin xyz="-0.003080308 -4.342331 -1.633749" rpy="0 0 0"/>
      <geometry>
        <mesh filename="package://ant_description/meshes/gaster.dae"/>
      </geometry>
    </visual>

    <inertial>
      <origin xyz="-0.007536868 -4.24358572 -1.27920505" rpy="0 0 0"/> 
      <mass value="10.5e-03"/> 
      <inertia
        ixx="4.5149767687e-02" 
        ixy="1.0052418988e-05" 
        ixz="5.1011709857e-06"
        iyy="3.4377606887e-02" 
        iyz="-6.6341991118e-03"
        izz="4.6317921879e-02"/>
    </inertial>
  </link>  

  <joint name="node_gaster" type="fixed">
    <parent link="node"/>
    <child link="gaster"/>
  </joint>

  <!-- cox front left link -->
  <link name="cox_f_l">
    <collision>
      <origin xyz="-0.5 0 0" rpy="0 0 0"/>
      <geometry>
        <mesh filename="package://ant_description/meshes/cox_f_l.dae"/>
      </geometry>
    </collision>

    <visual>
      <origin xyz="-0.5 0 0" rpy="0 0 0"/>
      <geometry>
        <mesh filename="package://ant_description/meshes/cox_f_l.dae"/>
      </geometry>
    </visual>

    <inertial>
      <origin xyz="-0.48765049  1.6566350000e-02 -1.5535011000e-01" rpy="0 0 0"/> 
      <mass value="0.04e-03"/>
      <inertia
        ixx="1.0102679884e-05" 
        ixy="2.2674534333e-06" 
        ixz="7.7135788286e-08"
        iyy="1.5637252431e-05" 
        iyz="7.5882038923e-07"
        izz="1.6299006925e-05"/>
    </inertial>
  </link>  

  <joint name="j_1_f_l" type="revolute">
    <parent link="thorax"/>
    <child link="cox_f_l"/>
    <origin xyz="-0.672313 5.942684 -0.2417362" rpy="0 0 0" />
    <axis xyz="0 0 1" />
    <limit effort="${j_eff}" velocity="${j_vel}" lower="${f_l_1_low}" upper="${f_l_1_upp}"/>
    <!-- <dynamics friction="500"/> --> 
  </joint>

  <!-- trochanter front left link -->
  <link name="trochanter_f_l">
    <collision>
      <origin xyz="-0.519615 -0.3 0" rpy="0 0 0.523599"/>
      <geometry>
        <mesh filename="package://ant_description/meshes/trochanter_f_l.dae"/>
      </geometry>
    </collision>

    <visual>
      <origin xyz="-0.519615 -0.3 0" rpy="0 0 0.523599"/>
      <geometry>
        <mesh filename="package://ant_description/meshes/trochanter_f_l.dae"/>
      </geometry>
    </visual>

    <inertial>
      <origin xyz="-0.77043483 -3.2823050000e-02  4.9396100000e-03" rpy="0 0 0.523599"/> 
      <mass value="0.02e-03"/>
      <inertia
        ixx="2.2993452021e-06" 
        ixy="6.9715962482e-07" 
        ixz="2.8722924018e-08"
        iyy="2.8440789053e-06" 
        iyz="-2.3697656786e-07"
        izz="3.0511624182e-06"/>
    </inertial>
  </link>  

  <joint name="j_2_f_l" type="revolute">
    <parent link="cox_f_l"/>
    <child link="trochanter_f_l"/>
    <origin xyz="-1.265769 0.454099 0.0176258" rpy="0 0 -0.523599" />
    <axis xyz="0 1 0" />
    <limit effort="${j_eff}" velocity="${j_vel}" lower="${f_l_2_low}" upper="${f_l_2_upp}"/>
    <!-- <dynamics friction="500"/> -->
  </joint> 

  <!-- femur front left link -->
  <link name="femur_f_l">
    <collision>
      <origin xyz="-2.580446 0.569617 0.32062271" rpy="0 0 0.523599"/>
      <geometry>
        <mesh filename="package://ant_description/meshes/femur_f_l.dae"/>
      </geometry>
    </collision>

    <visual>
      <origin xyz="-2.580446 0.569617 0.32062271" rpy="0 0 0.523599"/>
      <geometry>
        <mesh filename="package://ant_description/meshes/femur_f_l.dae"/>
      </geometry>
    </visual>

    <inertial>
      <origin xyz="-0.432542 -0.366687 2.5225760000e-02" rpy="0 0 0.523599"/> 
      <mass value="0.1e-03"/>
      <inertia
        ixx="7.2395381093e-05" 
        ixy="4.3550818145e-05" 
        ixz="7.6485127881e-06"
        iyy="3.7557387915e-05" 
        iyz="-1.0482999196e-05"
        izz="1.0023606719e-04"/>
    </inertial>
  </link> 

  <joint name="trochanter_femur_f_l" type="fixed">
    <parent link="trochanter_f_l"/>
    <child link="femur_f_l"/>
  </joint>  

  <!-- tibia front left link -->
  <link name="tibia_f_l">
    <collision>
      <origin xyz="0 0 -1.3" rpy="0 0 -0.523599"/>
      <geometry>
        <mesh filename="package://ant_description/meshes/tibia_f_l.dae"/>
      </geometry>
    </collision>

    <visual>
      <origin xyz="0 0 -1.3" rpy="0 0 -0.523599"/>
      <geometry>
        <mesh filename="package://ant_description/meshes/tibia_f_l.dae"/>
      </geometry>
    </visual>
    
    <inertial>
      <origin xyz="-0.019631 0.278709 -1.79721931" rpy="0 0 -0.523599"/> 
      <mass value="0.1e-03"/>
      <inertia
        ixx="1.4192610169e-04" 
        ixy="-2.2834938306e-06" 
        ixz="-1.0346178435e-05"
        iyy="1.3782398269e-04" 
        iyz="-2.4132529163e-05"
        izz="9.5237746087e-06"/>
    </inertial> 
  </link>  

  <joint name="j_3_f_l" type="revolute">
    <parent link="femur_f_l"/>
    <child link="tibia_f_l"/>
    <origin xyz="-4.155577 1.063204 0.2249814" rpy="0 0 1.0472" />
    <axis xyz="1 0 0" />
    <limit effort="${j_eff}" velocity="${j_vel}" lower="${f_lr_3_low}" upper="${f_lr_3_upp}"/>
    <!-- <dynamics friction="500"/> -->
  </joint> 

 <!-- tarsus front left link -->
  <link name="tarsus_f_l">
    <collision>
      <origin xyz="-1.164141 1.274724 -5.899937" rpy="0 0 -0.523599"/>
      <geometry>
        <mesh filename="package://ant_description/meshes/tarsus_f_l.dae"/>
      </geometry>
    </collision>

    <visual>
      <origin xyz="-1.164141 1.274724 -5.899937" rpy="0 0 -0.523599"/>
      <geometry>
        <mesh filename="package://ant_description/meshes/tarsus_f_l.dae"/>
      </geometry>
    </visual>

    <inertial>
      <origin xyz="0.197988 -0.332424 -0.92324425" rpy="0 0 -0.523599"/>
      <mass value="0.04e-03"/>
      <inertia
        ixx="4.0767281432e-05" 
        ixy="1.0157370563e-05" 
        ixz="-2.5479834505e-05"
        iyy="5.4536955924e-05" 
        iyz="1.3249849137e-05"
        izz="2.5113413747e-05"/>
    </inertial>
  </link> 

  <joint name="tibia_tarsus_f_l" type="fixed">
    <parent link="tibia_f_l"/>
    <child link="tarsus_f_l"/>
  </joint>

  <!-- cox front right link -->
  <link name="cox_f_r">
    <collision>
      <origin xyz="0.5 0 0" rpy="0 0 0"/>
      <geometry>
        <mesh filename="package://ant_description/meshes/cox_f_r.dae"/>
      </geometry>
    </collision>

    <visual>
      <origin xyz="0.5 0 0" rpy="0 0 0"/>
      <geometry>
        <mesh filename="package://ant_description/meshes/cox_f_r.dae"/>
      </geometry>
    </visual>

    <inertial>
      <origin xyz="0.57905302  5.1128630000e-02 -1.3051884000e-01" rpy="0 0 0"/> 
      <mass value="0.04e-03"/>
      <inertia
        ixx="1.0087579232e-05" 
        ixy="-2.1438399463e-06" 
        ixz="3.0633556934e-07"
        iyy="1.5033438155e-05" 
        iyz="7.6256837217e-07"
        izz="1.5792275298e-05"/>
    </inertial>
  </link>  

  <joint name="j_1_f_r" type="revolute">
    <parent link="thorax"/>
    <child link="cox_f_r"/>
    <origin xyz="0.69727071 5.942684 -0.2417362" rpy="0 0 0" />
    <axis xyz="0 0 1" />
    <limit effort="${j_eff}" velocity="${j_vel}" lower="${f_r_1_low}" upper="${f_r_1_upp}"/>
    <!-- <dynamics friction="500"/> --> 
  </joint>

  <!-- trochanter front right link -->
  <link name="trochanter_f_r">
    <collision>
      <origin xyz="0.519615 -0.3 0" rpy="0 0 -0.523599"/>
      <geometry>
        <mesh filename="package://ant_description/meshes/trochanter_f_r.dae"/>
      </geometry>
    </collision>

    <visual>
      <origin xyz="0.519615 -0.3 0" rpy="0 0 -0.523599"/>
      <geometry>
        <mesh filename="package://ant_description/meshes/trochanter_f_r.dae"/>
      </geometry>
    </visual>

    <inertial>
      <origin xyz="0.77043483 -3.2823050000e-02  4.9396100000e-03" rpy="0 0 -0.523599"/> 
      <mass value="0.02e-03"/>
      <inertia
        ixx="2.2993452021e-06" 
        ixy="-6.9715962482e-07" 
        ixz="-2.8722924018e-08"
        iyy="2.8440789053e-06" 
        iyz="-2.3697656786e-07"
        izz="3.0511624182e-06"/>
    </inertial>
  </link>  

  <joint name="j_2_f_r" type="revolute">
    <parent link="cox_f_r"/>
    <child link="trochanter_f_r"/>
    <origin xyz="1.265769 0.454099 0.0176258" rpy="0 0 0.523599" />
    <axis xyz="0 1 0" />
    <limit effort="${j_eff}" velocity="${j_vel}" lower="${f_r_2_low}" upper="${f_r_2_upp}"/>
    <!-- <dynamics friction="500"/> -->
  </joint> 

  <!-- femur front right link -->
  <link name="femur_f_r">
    <collision>
      <origin xyz="2.580446 0.569617 0.32062271" rpy="0 0 -0.523599"/>
      <geometry>
        <mesh filename="package://ant_description/meshes/femur_f_r.dae"/>
      </geometry>
    </collision>

    <visual>
      <origin xyz="2.580446 0.569617 0.32062271" rpy="0 0 -0.523599"/>
      <geometry>
        <mesh filename="package://ant_description/meshes/femur_f_r.dae"/>
      </geometry>
    </visual>

    <inertial>
      <origin xyz="0.432542 -0.366687 2.5225760000e-02" rpy="0 0 -0.523599"/> 
      <mass value="0.1e-03"/>
      <inertia
        ixx="7.2395381093e-05" 
        ixy="-4.3550818145e-05" 
        ixz="-7.6485127881e-06"
        iyy="3.7557387915e-05" 
        iyz="-1.0482999196e-05"
        izz="1.0023606719e-04"/>
    </inertial>
  </link> 

  <joint name="trochanter_femur_f_r" type="fixed">
    <parent link="trochanter_f_r"/>
    <child link="femur_f_r"/>
  </joint> 

  <!-- tibia front right link -->
  <link name="tibia_f_r">
    <collision>
      <origin xyz="0 0 -1.3" rpy="0 0 0.523599"/>
      <geometry>
        <mesh filename="package://ant_description/meshes/tibia_f_r.dae"/>
      </geometry>
    </collision>

    <visual>
      <origin xyz="0 0 -1.3" rpy="0 0 0.523599"/>
      <geometry>
        <mesh filename="package://ant_description/meshes/tibia_f_r.dae"/>
      </geometry>
    </visual>
    
    <inertial>
      <origin xyz="0.019631 0.278709 -1.79721931" rpy="0 0 0.523599"/> 
      <mass value="0.1e-03"/>
      <inertia
        ixx="1.4192610169e-04" 
        ixy="2.2834938306e-06" 
        ixz="1.0346178435e-05"
        iyy="1.3782398269e-04" 
        iyz="-2.4132529163e-05"
        izz="9.5237746087e-06"/>
    </inertial> 
  </link>  

  <joint name="j_3_f_r" type="revolute">
    <parent link="femur_f_r"/>
    <child link="tibia_f_r"/>
    <origin xyz="4.155577 1.063204 0.2249814" rpy="0 0 -1.0472" />
    <axis xyz="1 0 0" />
    <limit effort="${j_eff}" velocity="${j_vel}" lower="${f_lr_3_low}" upper="${f_lr_3_upp}"/>
    <!-- <dynamics friction="500"/> -->
  </joint>

 <!-- tarsus front right link -->
  <link name="tarsus_f_r">
    <collision>
      <origin xyz="1.164141 1.274724 -5.899937" rpy="0 0 0.523599"/>
      <geometry>
        <mesh filename="package://ant_description/meshes/tarsus_f_r.dae"/>
      </geometry>
    </collision>

    <visual>
      <origin xyz="1.164141 1.274724 -5.899937" rpy="0 0 0.523599"/>
      <geometry>
        <mesh filename="package://ant_description/meshes/tarsus_f_r.dae"/>
      </geometry>
    </visual>

    <inertial>
      <origin xyz="-0.197988 -0.332424 -0.92324425" rpy="0 0 0.523599"/>
      <mass value="0.04e-03"/>
      <inertia
        ixx="4.0767281432e-05" 
        ixy="-1.0157370563e-05" 
        ixz="2.5479834505e-05"
        iyy="5.4536955924e-05" 
        iyz="1.3249849137e-05"
        izz="2.5113413747e-05"/>
    </inertial>
  </link> 

  <joint name="tibia_tarsus_f_r" type="fixed">
    <parent link="tibia_f_r"/>
    <child link="tarsus_f_r"/>
  </joint>

  <!-- cox middle left link -->
  <link name="cox_m_l">
    <collision>
      <origin xyz="-0.5 0 0" rpy="0 0 0"/>
      <geometry>
        <mesh filename="package://ant_description/meshes/cox_m_l.dae"/>
      </geometry>
    </collision>

    <visual>
      <origin xyz="-0.5 0 0" rpy="0 0 0"/>
      <geometry>
        <mesh filename="package://ant_description/meshes/cox_m_l.dae"/>
      </geometry>
    </visual>

    <inertial>
      <origin xyz="-0.51716983  1.1915810000e-02 -1.3921484000e-01" rpy="0 0 0"/> 
      <mass value="0.04e-03"/>
      <inertia
        ixx="1.0434788363e-05" 
        ixy="-2.6462091739e-06" 
        ixz="-2.6974550523e-08"
        iyy="1.5178397598e-05" 
        iyz="8.5687458070e-07"
        izz="1.6513345971e-05"/>
    </inertial>
  </link>  

  <joint name="j_1_m_l" type="revolute">
    <parent link="thorax"/>
    <child link="cox_m_l"/>
    <origin xyz="-0.87320329 3.654325 -0.04402315" rpy="0 0 0" />
    <axis xyz="0 0 1" />
    <limit effort="${j_eff}" velocity="${j_vel}" lower="${m_l_1_low}" upper="${m_l_1_upp}"/>
    <!-- <dynamics friction="500"/> --> 
  </joint>

  <!-- trochanter middle left link -->
  <link name="trochanter_m_l">
    <collision>
      <origin xyz="-0.6 0 0" rpy="0 0 0"/>
      <geometry>
        <mesh filename="package://ant_description/meshes/trochanter_m_l.dae"/>
      </geometry>
    </collision>

    <visual>
      <origin xyz="-0.6 0 0" rpy="0 0 0"/>
      <geometry>
        <mesh filename="package://ant_description/meshes/trochanter_m_l.dae"/>
      </geometry>
    </visual>

    <inertial>
      <origin xyz="-0.55512966  1.4158560000e-02 -7.3947500000e-03" rpy="0 0 0"/> 
      <mass value="0.02e-03"/>
      <inertia
        ixx="2.2204178716e-06" 
        ixy="-6.7226740450e-07" 
        ixz="2.3827872471e-07"
        iyy="2.9717439293e-06" 
        iyz="-8.0081123133e-08"
        izz="3.0732874901e-06"/>
    </inertial>
  </link>  

  <joint name="j_2_m_l" type="revolute">
    <parent link="cox_m_l"/>
    <child link="trochanter_m_l"/>
    <origin xyz="-1.092786 -0.667436 0.15847855" rpy="0 0 0" />
    <axis xyz="0 1 0" />
    <limit effort="${j_eff}" velocity="${j_vel}" lower="${m_l_2_low}" upper="${m_l_2_upp}"/>
    <!-- <dynamics friction="500"/> -->
  </joint> 

  <!-- femur middle left link -->
  <link name="femur_m_l">
    <collision>
      <origin xyz="-3.031796 -1.037177 0.5874824" rpy="0 0 0"/>
      <geometry>
        <mesh filename="package://ant_description/meshes/femur_m_l.dae"/>
      </geometry>
    </collision>

    <visual>
      <origin xyz="-3.031796 -1.037177 0.5874824" rpy="0 0 0"/>
      <geometry>
        <mesh filename="package://ant_description/meshes/femur_m_l.dae"/>
      </geometry>
    </visual>

    <inertial>
      <origin xyz="-0.28026106 1.1244939000e-01 -6.3924120000e-02" rpy="0 0 0"/> 
      <mass value="0.075e-03"/>
      <inertia
        ixx="2.2667283158e-05" 
        ixy="-3.4240186618e-05" 
        ixz="1.8337460595e-05"
        iyy="9.1191896347e-05" 
        iyz="7.8406549877e-06"
        izz="1.0157579764e-04"/>
    </inertial>
  </link> 

  <joint name="trochanter_femur_m_l" type="fixed">
    <parent link="trochanter_m_l"/>
    <child link="femur_m_l"/>
  </joint>

  <!-- tibia middle left link -->
  <link name="tibia_m_l">
    <collision>
      <origin xyz="0.136808 0.375877 -1.3" rpy="0 0 -1.91986"/>
      <geometry>
        <mesh filename="package://ant_description/meshes/tibia_m_l.dae"/>
      </geometry>
    </collision>

    <visual>
      <origin xyz="0.136808 0.375877 -1.3" rpy="0 0 -1.91986"/>
      <geometry>
        <mesh filename="package://ant_description/meshes/tibia_m_l.dae"/>
      </geometry>
    </visual>
    
    <inertial>
      <origin xyz="0.122652 0.593339 -1.79632004" rpy="0 0 -1.91986"/> 
      <mass value="0.075e-03"/>
      <inertia
        ixx="9.5881662594e-05" 
        ixy="-4.1192128348e-06" 
        ixz="-2.9193862266e-05"
        iyy="1.0334704563e-04" 
        iyz="-1.3915701158e-05"
        izz="1.4942969068e-05"/>
    </inertial> 
  </link>  

  <joint name="j_3_m_l" type="revolute">
    <parent link="femur_m_l"/>
    <child link="tibia_m_l"/>
    <origin xyz="-4.794432 -1.923477 0.8121009" rpy="0 0 1.91986" />
    <axis xyz="1 0 0" />
    <limit effort="${j_eff}" velocity="${j_vel}" lower="${m_lr_3_low}" upper="${m_lr_3_upp}"/>
    <!-- <dynamics friction="500"/> -->
  </joint> 

 <!-- tarsus middle left z: -6.5016463 -->
  <link name="tarsus_m_l">
    <collision>
      <origin xyz="0.556888 1.563018 -6.0016463" rpy="0 0 -1.91986"/>
      <geometry>
        <mesh filename="package://ant_description/meshes/tarsus_m_l.dae"/>
      </geometry>
    </collision>

    <visual>
      <origin xyz="0.556888 1.563018 -6.0016463" rpy="0 0 -1.91986"/>
      <geometry>
        <mesh filename="package://ant_description/meshes/tarsus_m_l.dae"/>
      </geometry>
    </visual>

    <inertial>
      <origin xyz="-0.197988 -0.332424 -0.92324425" rpy="0 0 1.91986"/>
      <mass value="0.04e-03"/>
      <inertia
        ixx="5.3610128305e-05" 
        ixy="7.0895224381e-07" 
        ixz="-8.7743887975e-06"
        iyy="5.4646128905e-05" 
        iyz="4.8944350510e-06"
        izz="2.6908848602e-06"/>
    </inertial>
  </link> 

  <joint name="tibia_tarsus_m_l" type="fixed">
    <parent link="tibia_m_l"/>
    <child link="tarsus_m_l"/>
  </joint>

  <!-- cox middle right link -->
  <link name="cox_m_r">
    <collision>
      <origin xyz="0.5 0 0" rpy="0 0 0"/>
      <geometry>
        <mesh filename="package://ant_description/meshes/cox_m_r.dae"/>
      </geometry>
    </collision>

    <visual>
      <origin xyz="0.5 0 0" rpy="0 0 0"/>
      <geometry>
        <mesh filename="package://ant_description/meshes/cox_m_r.dae"/>
      </geometry>
    </visual>

    <inertial>
      <origin xyz="0.51717  1.1915810000e-02 -1.3921484000e-01" rpy="0 0 0"/> 
      <mass value="0.04e-03"/>
      <inertia
        ixx="1.0434788363e-05" 
        ixy="2.6462043310e-06" 
        ixz="2.6973863192e-08"
        iyy="1.5178399212e-05" 
        iyz="8.5687579141e-07"
        izz="1.6513345971e-05"/>
    </inertial>
  </link>  

  <joint name="j_1_m_r" type="revolute">
    <parent link="thorax"/>
    <child link="cox_m_r"/>
    <origin xyz="0.87320329 3.654325 -0.04402315" rpy="0 0 0" />
    <axis xyz="0 0 1" />
    <limit effort="${j_eff}" velocity="${j_vel}" lower="${m_r_1_low}" upper="${m_r_1_upp}"/>
    <!-- <dynamics friction="500"/> --> 
  </joint>

  <!-- trochanter middle right link -->
  <link name="trochanter_m_r">
    <collision>
      <origin xyz="0.6 0 0" rpy="0 0 0"/>
      <geometry>
        <mesh filename="package://ant_description/meshes/trochanter_m_r.dae"/>
      </geometry>
    </collision>

    <visual>
      <origin xyz="0.6 0 0" rpy="0 0 0"/>
      <geometry>
        <mesh filename="package://ant_description/meshes/trochanter_m_r.dae"/>
      </geometry>
    </visual>

    <inertial>
      <origin xyz="0.54487034  1.4158560000e-02 -7.3947500000e-03" rpy="0 0 0"/> 
      <mass value="0.02e-03"/>
      <inertia
        ixx="2.2204182857e-06" 
        ixy="6.7226767312e-07" 
        ixz="-2.3827948533e-07"
        iyy="2.9717444836e-06" 
        iyz="-8.0080433830e-08"
        izz="3.0732867264e-06"/>
    </inertial>
  </link>  

  <joint name="j_2_m_r" type="revolute">
    <parent link="cox_m_r"/>
    <child link="trochanter_m_r"/>
    <origin xyz="1.092786 -0.667436 0.15847855" rpy="0 0 0" />
    <axis xyz="0 1 0" />
    <limit effort="${j_eff}" velocity="${j_vel}" lower="${m_r_2_low}" upper="${m_r_2_upp}"/>
    <!-- <dynamics friction="500"/> -->
  </joint> 

  <!-- femur middle right link -->
  <link name="femur_m_r">
    <collision>
      <origin xyz="3.031796 -1.037177 0.5874824" rpy="0 0 0"/>
      <geometry>
        <mesh filename="package://ant_description/meshes/femur_m_r.dae"/>
      </geometry>
    </collision>

    <visual>
      <origin xyz="3.031796 -1.037177 0.5874824" rpy="0 0 0"/>
      <geometry>
        <mesh filename="package://ant_description/meshes/femur_m_r.dae"/>
      </geometry>
    </visual>

    <inertial>
      <origin xyz="0.28026106 1.1244939000e-01 -6.3924120000e-02" rpy="0 0 0"/> 
      <mass value="0.075e-03"/>
      <inertia
        ixx="2.2743406758e-05" 
        ixy="3.4229801867e-05" 
        ixz="-1.8346448549e-05"
        iyy="9.0970617181e-05" 
        iyz="7.8811283478e-06"
        izz="1.0138090585e-04"/>
    </inertial>
  </link> 

  <joint name="trochanter_femur_m_r" type="fixed">
    <parent link="trochanter_m_r"/>
    <child link="femur_m_r"/>
  </joint>

  <!-- tibia middle right link -->
  <link name="tibia_m_r">
    <collision>
      <origin xyz="-0.136808 0.375877 -1.3" rpy="0 0 1.91986"/>
      <geometry>
        <mesh filename="package://ant_description/meshes/tibia_m_r.dae"/>
      </geometry>
    </collision>

    <visual>
      <origin xyz="-0.136808 0.375877 -1.3" rpy="0 0 1.91986"/>
      <geometry>
        <mesh filename="package://ant_description/meshes/tibia_m_r.dae"/>
      </geometry>
    </visual>
    
    <inertial>
      <origin xyz="-0.122652 0.593339 -1.79632004" rpy="0 0 1.91986"/> 
      <mass value="0.075e-03"/>
      <inertia
        ixx="9.5881662594e-05" 
        ixy="4.1192107262e-06" 
        ixz="2.9193858892e-05"
        iyy="1.0334705237e-04" 
        iyz="-1.3915695254e-05"
        izz="1.4942967381e-05"/>
    </inertial> 
  </link>  

  <joint name="j_3_m_r" type="revolute">
    <parent link="femur_m_r"/>
    <child link="tibia_m_r"/>
    <origin xyz="4.794432 -1.923477 0.8121009" rpy="0 0 -1.91986" />
    <axis xyz="1 0 0" />
    <limit effort="${j_eff}" velocity="${j_vel}" lower="${m_lr_3_low}" upper="${m_lr_3_upp}"/>
    <!-- <dynamics friction="500"/> -->
  </joint> 

 <!-- tarsus middle right link z: -6.5016463 -->
  <link name="tarsus_m_r">
    <collision>
      <origin xyz="-0.556888 1.563018 -6.0016463" rpy="0 0 1.91986"/>
      <geometry>
        <mesh filename="package://ant_description/meshes/tarsus_m_r.dae"/>
      </geometry>
    </collision>

    <visual>
      <origin xyz="-0.556888 1.563018 -6.0016463" rpy="0 0 1.91986"/>
      <geometry>
        <mesh filename="package://ant_description/meshes/tarsus_m_r.dae"/>
      </geometry>
    </visual>

    <inertial>
      <origin xyz="0.197988 -0.332424 -0.92324425" rpy="0 0 -1.91986"/>
      <mass value="0.04e-03"/>
      <inertia
        ixx="5.3610128305e-05" 
        ixy="-7.0895224381e-07" 
        ixz="8.7743887975e-06"
        iyy="5.4646128905e-05" 
        iyz="4.8944350510e-06"
        izz="2.6908848602e-06"/>
    </inertial> 
  </link> 

  <joint name="tibia_tarsus_m_r" type="fixed">
    <parent link="tibia_m_r"/>
    <child link="tarsus_m_r"/>
  </joint>

  <!-- cox rear left link -->
  <link name="cox_r_l">
    <collision>
      <origin xyz="-0.5 -0.5 0" rpy="0 0 0"/>
      <geometry>
        <mesh filename="package://ant_description/meshes/cox_r_l.dae"/>
      </geometry>
    </collision>

    <visual>
      <origin xyz="-0.5 -0.5 0" rpy="0 0 0"/>
      <geometry>
        <mesh filename="package://ant_description/meshes/cox_r_l.dae"/>
      </geometry>
    </visual>

    <inertial>
      <origin xyz="-0.54993608 -0.55808213 -1.8706305000e-01" rpy="0 0 0"/> 
      <mass value="0.04e-03"/>
      <inertia
        ixx="1.2970585090e-05" 
        ixy="-3.3190972489e-06" 
        ixz="-5.8636351686e-07"
        iyy="1.1863979209e-05" 
        iyz="5.3221663726e-07"
        izz="1.5899537610e-05"/>
    </inertial>
  </link>  

  <joint name="j_1_r_l" type="revolute">
    <parent link="thorax"/>
    <child link="cox_r_l"/>
    <origin xyz="-1.004655 2.310507 -0.4687623 " rpy="0 0 0" />
    <axis xyz="0 0 1" />
    <limit effort="${j_eff}" velocity="${j_vel}" lower="${r_l_1_low}" upper="${r_l_1_upp}"/>
    <!-- <dynamics friction="500"/> --> 
  </joint>

  <!-- trochanter rear left link -->
  <link name="trochanter_r_l">
    <collision>
      <origin xyz="0 -0.1 0" rpy="0 0 -0.785398"/>
      <geometry>
        <mesh filename="package://ant_description/meshes/trochanter_r_l.dae"/>
      </geometry>
    </collision>

    <visual>
      <origin xyz="0 -0.1 0" rpy="0 0 -0.785398"/>
      <geometry>
        <mesh filename="package://ant_description/meshes/trochanter_r_l.dae"/>
      </geometry>
    </visual>

    <inertial>
      <origin xyz="0.12571826  0.9669486000e-01 -3.1070070000e-02" rpy="0 0 -0.785398"/> 
      <mass value="0.02e-03"/>
      <inertia
        ixx="3.0146359372e-06" 
        ixy="-7.6893701448e-07" 
        ixz="2.5320343273e-07"
        iyy="2.5886215870e-06" 
        iyz="6.8494263153e-09"
        izz="3.3175529044e-06"/>
    </inertial>
  </link> 

  <joint name="j_2_r_l" type="revolute">
    <parent link="cox_r_l"/>
    <child link="trochanter_r_l"/>
    <!-- -0.955945 -1.6218341 -->
    <origin xyz="-1.455945 -1.5218341 0.1198297" rpy="0 0 0.785398" />
    <axis xyz="0 1 0" />
    <limit effort="${j_eff}" velocity="${j_vel}" lower="${r_l_2_low}" upper="${r_l_2_upp}"/>
    <!-- <dynamics friction="500"/> -->
  </joint> 

  <!-- femur rear left link -->
  <link name="femur_r_l">
    <collision>
      <origin xyz="-3.577342 0.083712 0.8584707" rpy="0 0 -0.785398"/>
      <geometry>
        <mesh filename="package://ant_description/meshes/femur_r_l.dae"/>
      </geometry>
    </collision>

    <visual>
      <origin xyz="-3.577342 -0.083712 0.8584707" rpy="0 0 -0.785398"/>
      <geometry>
        <mesh filename="package://ant_description/meshes/femur_r_l.dae"/>
      </geometry>
    </visual>

    <inertial>
      <origin xyz="0.665222 0.039724 -1.0237488000e-01" rpy="0 0 -0.785398"/> 
      <mass value="0.125e-03"/>
      <inertia
        ixx="1.6384300407e-04" 
        ixy="-1.4403868632e-04" 
        ixz="4.4873065055e-05"
        iyy="1.6910132607e-04" 
        iyz="4.4723802014e-05"
        izz="2.9485162178e-04"/>
    </inertial>
  </link>

  <joint name="trochanter_femur_r_l" type="fixed">
    <parent link="trochanter_r_l"/>
    <child link="femur_r_l"/>
  </joint>

  <!-- tibia rear left link -->
  <link name="tibia_r_l">
    <collision>
      <origin xyz="0 0 -1.8" rpy="0 0 -2.44346"/>
      <geometry>
        <mesh filename="package://ant_description/meshes/tibia_r_l.dae"/>
      </geometry>
    </collision>

    <visual>
      <origin xyz="0 0 -1.8" rpy="0 0 -2.44346"/>
      <geometry>
        <mesh filename="package://ant_description/meshes/tibia_r_l.dae"/>
      </geometry>
    </visual>
    
    <inertial>
      <origin xyz="0.00756 0.24018 -2.10939386" rpy="0 0 -2.44346"/> 
      <mass value="0.125e-03"/>
      <inertia
        ixx="2.4117078880e-04" 
        ixy="-1.6511402461e-06" 
        ixz="-6.2135014015e-06"
        iyy="2.2607524023e-04" 
        iyz="-6.0465167705e-05"
        izz="2.2596038406e-05"/>
    </inertial> 
  </link>  

  <joint name="j_3_r_l" type="revolute">
    <parent link="femur_r_l"/>
    <child link="tibia_r_l"/>
    <origin xyz="-6.642246 -0.535843 1.3238474" rpy="0 0 1.5708" />
    <axis xyz="1 0 0" />
    <limit effort="${j_eff}" velocity="${j_vel}" lower="${r_lr_3_low}" upper="${r_lr_3_upp}"/>
    <!-- <dynamics friction="500"/> -->
  </joint> 

 <!-- tarsus rear left link -->
  <link name="tarsus_r_l">
    <collision>
      <origin xyz="-1.452104 1.655428 -5.8634428" rpy="0 0 -2.44346"/>
      <geometry>
        <mesh filename="package://ant_description/meshes/tarsus_r_l.dae"/>
      </geometry>
    </collision>

    <visual>
      <origin xyz="-1.452104 1.655428 -5.8634428" rpy="0 0 -2.44346"/>
      <geometry>
        <mesh filename="package://ant_description/meshes/tarsus_r_l.dae"/>
      </geometry>
    </visual>

    <inertial>
      <origin xyz="5.2596670000e-02 -3.5839279000e-01 -1.80963057" rpy="0 0 -2.44346"/>
      <mass value="0.04e-03"/>
      <inertia
        ixx="6.7722728852e-05" 
        ixy="1.5179356065e-06" 
        ixz="1.8027405940e-06"
        iyy="3.9337978443e-05" 
        iyz="-3.3111218232e-05"
        izz="2.9311718913e-05"/>
    </inertial>
  </link> 

  <joint name="tibia_tarsus_r_l" type="fixed">
    <parent link="tibia_r_l"/>
    <child link="tarsus_r_l"/>
  </joint>

  <!-- cox rear right link -->
  <link name="cox_r_r">
    <collision>
      <origin xyz="0.5 -0.5 0" rpy="0 0 0"/>
      <geometry>
        <mesh filename="package://ant_description/meshes/cox_r_r.dae"/>
      </geometry>
    </collision>

    <visual>
      <origin xyz="0.5 -0.5 0" rpy="0 0 0"/>
      <geometry>
        <mesh filename="package://ant_description/meshes/cox_r_r.dae"/>
      </geometry>
    </visual>

    <inertial>
      <origin xyz="0.5558994 -0.58611938 -1.8706305000e-01" rpy="0 0 0"/> 
      <mass value="0.04e-03"/>
      <inertia
        ixx="1.2963991515e-05" 
        ixy="3.3824590201e-06" 
        ixz="5.9142635199e-07"
        iyy="1.1868066068e-05" 
        iyz="4.1788230568e-07"
        izz="1.6002661208e-05"/>
    </inertial>
  </link>  

  <joint name="j_1_r_r" type="revolute">
    <parent link="thorax"/>
    <child link="cox_r_r"/>
    <origin xyz="0.996461 2.346683 -0.5018439" rpy="0 0 0" />
    <axis xyz="0 0 1" />
    <limit effort="${j_eff}" velocity="${j_vel}" lower="${r_r_1_low}" upper="${r_r_1_upp}"/>
    <!-- <dynamics friction="500"/> --> 
  </joint>

  <!-- trochanter rear right link -->
  <link name="trochanter_r_r">
    <collision>
      <origin xyz="0 -0.1 0" rpy="0 0 0.785398"/>
      <geometry>
        <mesh filename="package://ant_description/meshes/trochanter_r_r.dae"/>
      </geometry>
    </collision>

    <visual>
      <origin xyz="0 -0.1 0" rpy="0 0 0.785398"/>
      <geometry>
        <mesh filename="package://ant_description/meshes/trochanter_r_r.dae"/>
      </geometry>
    </visual>

    <inertial>
      <origin xyz="0.12571826  0.9669486000e-01 -3.1070070000e-02" rpy="0 0 0.785398"/> 
      <mass value="0.02e-03"/>
      <inertia
        ixx="3.0146359372e-06" 
        ixy="7.6893701448e-07" 
        ixz="-2.5320343273e-07"
        iyy="2.5886215870e-06" 
        iyz="6.8494263153e-09"
        izz="3.3175529044e-06"/>
    </inertial>
  </link> 

  <joint name="j_2_r_r" type="revolute">
    <parent link="cox_r_r"/>
    <child link="trochanter_r_r"/>
    <origin xyz="1.455945 -1.5218341 0.1198297" rpy="0 0 -0.785398" />
    <axis xyz="0 1 0" />
    <limit effort="${j_eff}" velocity="${j_vel}" lower="${r_r_2_low}" upper="${r_r_2_upp}"/>
    <!-- <dynamics friction="500"/> -->
  </joint> 

  <!-- femur rear right link -->
  <link name="femur_r_r">
    <collision>
      <origin xyz="3.577342 0.083712 0.8584707" rpy="0 0 0.785398"/>
      <geometry>
        <mesh filename="package://ant_description/meshes/femur_r_r.dae"/>
      </geometry>
    </collision>

    <visual>
      <origin xyz="3.577342 -0.083712 0.8584707" rpy="0 0 0.785398"/>
      <geometry>
        <mesh filename="package://ant_description/meshes/femur_r_r.dae"/>
      </geometry>
    </visual>

    <inertial>
      <origin xyz="-0.665222 0.039724 -1.0237488000e-01" rpy="0 0 0.785398"/> 
      <mass value="0.125e-03"/>
      <inertia
        ixx="1.6384300407e-04" 
        ixy="1.4403868632e-04" 
        ixz="-4.4873065055e-05"
        iyy="1.6910132607e-04" 
        iyz="4.4723802014e-05"
        izz="2.9485162178e-04"/>
    </inertial>
  </link>

  <joint name="trochanter_femur_r_r" type="fixed">
    <parent link="trochanter_r_r"/>
    <child link="femur_r_r"/>
  </joint>

  <!-- tibia rear right link -->
  <link name="tibia_r_r">
    <collision>
      <origin xyz="0 0 -1.8" rpy="0 0 2.44346"/>
      <geometry>
        <mesh filename="package://ant_description/meshes/tibia_r_r.dae"/>
      </geometry>
    </collision>

    <visual>
      <origin xyz="0 0 -1.8" rpy="0 0 2.44346"/>
      <geometry>
        <mesh filename="package://ant_description/meshes/tibia_r_r.dae"/>
      </geometry>
    </visual>
    
    <inertial>
      <origin xyz="-0.00756 0.24018 -2.10939386" rpy="0 0 2.44346"/> 
      <mass value="0.125e-03"/>
      <inertia
        ixx="2.4117078880e-04" 
        ixy="1.6511402461e-06" 
        ixz="6.2135014015e-06"
        iyy="2.2607524023e-04" 
        iyz="-6.0465167705e-05"
        izz="2.2596038406e-05"/>
    </inertial> 
  </link>  

  <joint name="j_3_r_r" type="revolute">
    <parent link="femur_r_r"/>
    <child link="tibia_r_r"/>
    <origin xyz="6.642246 -0.535843 1.3238474" rpy="0 0 -1.5708" />
    <axis xyz="1 0 0" />
    <limit effort="${j_eff}" velocity="${j_vel}" lower="${r_lr_3_low}" upper="${r_lr_3_upp}"/>
    <!-- <dynamics friction="500"/> -->
  </joint> 

 <!-- tarsus rear left link -->
  <link name="tarsus_r_r">
    <collision>
      <origin xyz="1.452104 1.655428 -5.8634428" rpy="0 0 2.44346"/>
      <geometry>
        <mesh filename="package://ant_description/meshes/tarsus_r_r.dae"/>
      </geometry>
    </collision>

    <visual>
      <origin xyz="1.452104 1.655428 -5.8634428" rpy="0 0 2.44346"/>
      <geometry>
        <mesh filename="package://ant_description/meshes/tarsus_r_r.dae"/>
      </geometry>
    </visual>

    <inertial>
      <origin xyz="-5.2596670000e-02 -3.5839279000e-01 -1.80963057" rpy="0 0 2.44346"/>
      <mass value="0.04e-03"/>
      <inertia
        ixx="6.7722728852e-05" 
        ixy="-1.5179356065e-06" 
        ixz="-1.8027405940e-06"
        iyy="3.9337978443e-05" 
        iyz="-3.3111218232e-05"
        izz="2.9311718913e-05"/>
    </inertial>
  </link> 

  <joint name="tibia_tarsus_r_r" type="fixed">
    <parent link="tibia_r_r"/>
    <child link="tarsus_r_r"/>
  </joint>

  <transmission name="transm_f_l_1">
    <type>transmission_interface/SimpleTransmission</type>
    <joint name="j_1_f_l">
      <hardwareInterface>hardware_interface/EffortJointInterface</hardwareInterface>    
    </joint>
    <actuator name="m_f_l_1">
      <hardwareInterface>hardware_interface/EffortJointInterface</hardwareInterface>
      <mechanicalReduction>1</mechanicalReduction>
    </actuator>
  </transmission>

  <transmission name="transm_f_l_2">
    <type>transmission_interface/SimpleTransmission</type>
    <joint name="j_2_f_l">
      <hardwareInterface>hardware_interface/EffortJointInterface</hardwareInterface>    
    </joint>
    <actuator name="m_f_l_2">
      <hardwareInterface>hardware_interface/EffortJointInterface</hardwareInterface>
      <mechanicalReduction>1</mechanicalReduction>
    </actuator>
  </transmission>

  <transmission name="transm_f_l_3">
    <type>transmission_interface/SimpleTransmission</type>
    <joint name="j_3_f_l">
      <hardwareInterface>hardware_interface/EffortJointInterface</hardwareInterface>    
    </joint>
    <actuator name="m_f_l_3">
      <hardwareInterface>hardware_interface/EffortJointInterface</hardwareInterface>
      <mechanicalReduction>1</mechanicalReduction>
    </actuator>
  </transmission>  

  <transmission name="transm_f_r_1">
    <type>transmission_interface/SimpleTransmission</type>
    <joint name="j_1_f_r">
      <hardwareInterface>hardware_interface/EffortJointInterface</hardwareInterface>    
    </joint>
    <actuator name="m_f_r_1">
      <hardwareInterface>hardware_interface/EffortJointInterface</hardwareInterface>
      <mechanicalReduction>1</mechanicalReduction>
    </actuator>
  </transmission>

  <transmission name="transm_f_r_2">
    <type>transmission_interface/SimpleTransmission</type>
    <joint name="j_2_f_r">
      <hardwareInterface>hardware_interface/EffortJointInterface</hardwareInterface>    
    </joint>
    <actuator name="m_f_r_2">
      <hardwareInterface>hardware_interface/EffortJointInterface</hardwareInterface>
      <mechanicalReduction>1</mechanicalReduction>
    </actuator>
  </transmission>

  <transmission name="transm_f_r_3">
    <type>transmission_interface/SimpleTransmission</type>
    <joint name="j_3_f_r">
      <hardwareInterface>hardware_interface/EffortJointInterface</hardwareInterface>    
    </joint>
    <actuator name="m_f_r_3">
      <hardwareInterface>hardware_interface/EffortJointInterface</hardwareInterface>
      <mechanicalReduction>1</mechanicalReduction>
    </actuator>
  </transmission> 

  <transmission name="transm_m_l_1">
    <type>transmission_interface/SimpleTransmission</type>
    <joint name="j_1_m_l">
      <hardwareInterface>hardware_interface/EffortJointInterface</hardwareInterface>    
    </joint>
    <actuator name="m_m_l_1">
      <hardwareInterface>hardware_interface/EffortJointInterface</hardwareInterface>
      <mechanicalReduction>1</mechanicalReduction>
    </actuator>
  </transmission>

  <transmission name="transm_m_l_2">
    <type>transmission_interface/SimpleTransmission</type>
    <joint name="j_2_m_l">
      <hardwareInterface>hardware_interface/EffortJointInterface</hardwareInterface>   
    </joint>
    <actuator name="m_m_l_2">
      <hardwareInterface>hardware_interface/EffortJointInterface</hardwareInterface>
      <mechanicalReduction>1</mechanicalReduction>
    </actuator>
  </transmission>

  <transmission name="transm_m_l_3">
    <type>transmission_interface/SimpleTransmission</type>
    <joint name="j_3_m_l">
      <hardwareInterface>hardware_interface/EffortJointInterface</hardwareInterface>    
    </joint>
    <actuator name="m_m_l_3">
      <hardwareInterface>hardware_interface/EffortJointInterface</hardwareInterface>
      <mechanicalReduction>1</mechanicalReduction>
    </actuator>
  </transmission> 

  <transmission name="transm_m_r_1">
    <type>transmission_interface/SimpleTransmission</type>
    <joint name="j_1_m_r">
      <hardwareInterface>hardware_interface/EffortJointInterface</hardwareInterface>    
    </joint>
    <actuator name="m_m_l_r">
      <hardwareInterface>hardware_interface/EffortJointInterface</hardwareInterface>
      <mechanicalReduction>1</mechanicalReduction>
    </actuator>
  </transmission>

  <transmission name="transm_m_r_2">
    <type>transmission_interface/SimpleTransmission</type>
    <joint name="j_2_m_r">
      <hardwareInterface>hardware_interface/EffortJointInterface</hardwareInterface>    
    </joint>
    <actuator name="m_m_r_2">
      <hardwareInterface>hardware_interface/EffortJointInterface</hardwareInterface>
      <mechanicalReduction>1</mechanicalReduction>
    </actuator>
  </transmission>

  <transmission name="transm_m_r_3">
    <type>transmission_interface/SimpleTransmission</type>
    <joint name="j_3_m_r">
      <hardwareInterface>hardware_interface/EffortJointInterface</hardwareInterface>    
    </joint>
    <actuator name="m_m_r_3">
      <hardwareInterface>hardware_interface/EffortJointInterface</hardwareInterface>
      <mechanicalReduction>1</mechanicalReduction>
    </actuator>
  </transmission> 

  <transmission name="transm_r_l_1">
    <type>transmission_interface/SimpleTransmission</type>
    <joint name="j_1_r_l">
      <hardwareInterface>hardware_interface/EffortJointInterface</hardwareInterface>    
    </joint>
    <actuator name="m_r_l_1">
      <hardwareInterface>hardware_interface/EffortJointInterface</hardwareInterface>
      <mechanicalReduction>1</mechanicalReduction>
    </actuator>
  </transmission>

  <transmission name="transm_r_l_2">
    <type>transmission_interface/SimpleTransmission</type>
    <joint name="j_2_r_l">
      <hardwareInterface>hardware_interface/EffortJointInterface</hardwareInterface>  
    </joint>
    <actuator name="m_r_l_2">
      <hardwareInterface>hardware_interface/EffortJointInterface</hardwareInterface>
      <mechanicalReduction>1</mechanicalReduction>
    </actuator>
  </transmission>

  <transmission name="transm_r_l_3">
    <type>transmission_interface/SimpleTransmission</type>
    <joint name="j_3_r_l">
      <hardwareInterface>hardware_interface/EffortJointInterface</hardwareInterface>    
    </joint>
    <actuator name="m_r_l_3">
      <hardwareInterface>hardware_interface/EffortJointInterface</hardwareInterface>
      <mechanicalReduction>1</mechanicalReduction>
    </actuator>
  </transmission> 

  <transmission name="transm_r_r_1">
    <type>transmission_interface/SimpleTransmission</type>
    <joint name="j_1_r_r">
      <hardwareInterface>hardware_interface/EffortJointInterface</hardwareInterface>    
    </joint>
    <actuator name="m_r_r_1">
      <hardwareInterface>hardware_interface/EffortJointInterface</hardwareInterface>
      <mechanicalReduction>1</mechanicalReduction>
    </actuator>
  </transmission>

  <transmission name="transm_r_r_2">
    <type>transmission_interface/SimpleTransmission</type>
    <joint name="j_2_r_r">
      <hardwareInterface>hardware_interface/EffortJointInterface</hardwareInterface>    
    </joint>
    <actuator name="m_r_r_2">
      <hardwareInterface>hardware_interface/EffortJointInterface</hardwareInterface>
      <mechanicalReduction>1</mechanicalReduction>
    </actuator>
  </transmission>

  <transmission name="transm_r_r_3">
    <type>transmission_interface/SimpleTransmission</type>
    <joint name="j_3_r_r">
      <hardwareInterface>hardware_interface/EffortJointInterface</hardwareInterface>    
    </joint>
    <actuator name="m_r_r_3">
      <hardwareInterface>hardware_interface/EffortJointInterface</hardwareInterface>
      <mechanicalReduction>1</mechanicalReduction>
    </actuator>
  </transmission>

  <gazebo reference="tarsus_f_l">    
    <mu1>100</mu1>
    <mu2>50</mu2>
  </gazebo>

  <gazebo reference="tarsus_f_r">    
    <mu1>100</mu1>
    <mu2>50</mu2>
  </gazebo>

  <gazebo reference="tarsus_m_l">    
    <mu1>100</mu1>
    <mu2>50</mu2>
  </gazebo>

  <gazebo reference="tarsus_m_r">    
    <mu1>100</mu1>
    <mu2>50</mu2>
  </gazebo>

  <gazebo reference="tarsus_r_r">    
    <mu1>100</mu1>
    <mu2>50</mu2>
  </gazebo>

  <gazebo reference="tarsus_r_l">    
    <mu1>100</mu1>
    <mu2>50</mu2>
  </gazebo>

  <gazebo>
    <plugin filename="libgazebo_ros_control.so" name="gazebo_ros_control">
      <robotNamespace>/ant</robotNamespace>
    </plugin>
  </gazebo>
  
</robot>
