<?xml version="1.0" ?>
<robot name="ant"  xmlns:xacro="http://www.ros.org/wiki/xacro">

  <!-- cox front left link -->
  <link name="cox_f_l">
    <collision>
      <origin xyz="-0.5 0 0" rpy="0 0 0"/>
      <geometry>
        <mesh filename="package://ant_description/meshes/cox_f_l.stl"/>
      </geometry>
    </collision>

    <visual>
      <origin xyz="-0.5 0 0" rpy="0 0 0"/>
      <geometry>
        <mesh filename="package://ant_description/meshes/cox_f_l.stl"/>
      </geometry>
    </visual>

    <inertial>
      <origin xyz="-0.48765049  1.6566350000e-02 -1.5535011000e-01" rpy="0 0 0"/> 
      <mass value="3"/>
      <inertia
        ixx="7.5768846297e-01" 
        ixy="1.7005788603e-01" 
        ixz="5.7852710942e-03"
        iyy="1.1727972097e+00" 
        iyz="5.6909853774e-02"
        izz="1.2224152912e+00"/>
    </inertial>
  </link>  

  <joint name="thorax_cox_f_l" type="revolute">
    <parent link="thorax"/>
    <child link="cox_f_l"/>
    <origin xyz="-0.672313 5.942684 -0.2417362" rpy="0 0 0" />
    <axis xyz="0 0 1" />
    <limit effort="${j_eff}" velocity="${j_vel}" lower="${l_1_low}" upper="${l_1_upp}"/>
  </joint>

  <!-- trochanter front left link -->
  <link name="trochanter_f_l">
    <collision>
      <origin xyz="-0.6 0 0" rpy="0 0 0"/>
      <geometry>
        <mesh filename="package://ant_description/meshes/trochanter_f_l.stl"/>
      </geometry>
    </collision>

    <visual>
      <origin xyz="-0.6 0 0" rpy="0 0 0"/>
      <geometry>
        <mesh filename="package://ant_description/meshes/trochanter_f_l.stl"/>
      </geometry>
    </visual>

    <inertial>
      <origin xyz="-0.77043483 -3.2823050000e-02  4.9396100000e-03" rpy="0 0 0"/> 
      <mass value="1"/>
      <inertia
        ixx="1.1496440267e-01" 
        ixy="3.4858491007e-02" 
        ixz="1.4360769641e-03"
        iyy="1.4220481517e-01" 
        iyz="-1.1846910889e-02"
        izz="1.5255737899e-01"/>
    </inertial>
  </link>  

  <joint name="cox_trochanter_f_l" type="revolute">
    <parent link="cox_f_l"/>
    <child link="trochanter_f_l"/>
    <origin xyz="-1.265769 0.454099 0.0176258" rpy="0 0 0" />
    <axis xyz="0 1 0" />
    <limit effort="2.8" velocity="5.6548668" lower="0" upper="1" />
  </joint> 

  <!-- femur front left link -->
  <link name="femur_f_l">
    <collision>
      <origin xyz="-1.949923 1.783526 0.32062271" rpy="0 0 0"/>
      <geometry>
        <mesh filename="package://ant_description/meshes/femur_f_l.stl"/>
      </geometry>
    </collision>

    <visual>
      <origin xyz="-1.949923 1.783526 0.32062271" rpy="0 0 0"/>
      <geometry>
        <mesh filename="package://ant_description/meshes/femur_f_l.stl"/>
      </geometry>
    </visual>

    <inertial>
      <origin xyz="-0.5579356 -1.0128977000e-01  2.5225760000e-02" rpy="0 0 0"/> 
      <mass value="5"/>
      <inertia
        ixx="3.6197642457e+00" 
        ixy="2.1775364163e+00" 
        ixz="3.8242520797e-01"
        iyy="1.8778697845e+00" 
        iyz="-5.2415364462e-01"
        izz="5.0117853596e+00"/>
    </inertial>
  </link> 

  <joint name="trochanter_femur_f_l" type="fixed">
    <parent link="trochanter_f_l"/>
    <child link="femur_f_l"/>
  </joint>  

  <!-- tibia front left link -->
  <link name="tibia_f_l">
    <collision>
      <origin xyz="0 0 -1.3" rpy="0 0 -0.523599"/>
      <geometry>
        <mesh filename="package://ant_description/meshes/tibia_f_l.stl"/>
      </geometry>
    </collision>

    <visual>
      <origin xyz="0 0 -1.3" rpy="0 0 -0.523599"/>
      <geometry>
        <mesh filename="package://ant_description/meshes/tibia_f_l.stl"/>
      </geometry>
    </visual>
    
    <inertial>
      <origin xyz="-3.7722210000e-02 -6.1037620000e-02 -1.79721931" rpy="0 0 -0.523599"/> 
      <mass value="4"/>
      <inertia
        ixx="5.6769505167e+00" 
        ixy="-9.1392209980e-02" 
        ixz="-4.1384680225e-01"
        iyy="5.5128989027e+00" 
        iyz="-9.6529489518e-01"
        izz="3.8081446228e-01"/>
    </inertial> 
  </link>  

  <joint name="femur_tibia_f_l" type="revolute">
    <parent link="femur_f_l"/>
    <child link="tibia_f_l"/>
    <origin xyz="-3.067233 2.99855 0.2249814" rpy="0 0 0.523599" />
    <axis xyz="1 0 0" />
    <limit effort="2.8" velocity="5.6548668" lower="0" upper="1" />
  </joint> 

 <!-- tarsus front left link -->
  <link name="tarsus_f_l">
    <collision>
      <origin xyz="-1.164141 1.274724 -5.899937" rpy="0 0 -0.523599"/>
      <geometry>
        <mesh filename="package://ant_description/meshes/tarsus_f_l.stl"/>
      </geometry>
    </collision>

    <visual>
      <origin xyz="-1.164141 1.274724 -5.899937" rpy="0 0 -0.523599"/>
      <geometry>
        <mesh filename="package://ant_description/meshes/tarsus_f_l.stl"/>
      </geometry>
    </visual>

    <inertial>
      <origin xyz="0.197988 -0.332424 -0.92324425" rpy="0 0 -0.523599"/>
      <mass value="2"/>
      <inertia
        ixx="2.0383412574e+00" 
        ixy="5.0790120060e-01" 
        ixz="-1.2739759948e+00"
        iyy="2.7268712920e+00" 
        iyz="6.6243787205e-01"
        izz="1.2557246830e+00"/>
    </inertial>
  </link> 

  <joint name="tibia_tarsus_f_l" type="fixed">
    <parent link="tibia_f_l"/>
    <child link="tarsus_f_l"/>
  </joint> 
  
</robot>
