<?xml version="1.0" ?>
<robot name="ant"  xmlns:xacro="http://www.ros.org/wiki/xacro">

  <xacro:property name="j_eff" value="10000" />
  <xacro:property name="j_vel" value="10000" />

  <xacro:property name="f_l_1_low" value="-0.4" />
  <xacro:property name="f_l_1_upp" value="0.6" />
  <xacro:property name="f_r_1_low" value="-0.6" />
  <xacro:property name="f_r_1_upp" value="0.4" />

  <xacro:property name="m_l_1_low" value="-0.65" />
  <xacro:property name="m_l_1_upp" value="0.15" />
  <xacro:property name="m_r_1_low" value="-0.15" />
  <xacro:property name="m_r_1_upp" value="0.65" />

  <xacro:property name="r_l_1_low" value="-0.4" />
  <xacro:property name="r_l_1_upp" value="0.25" />
  <xacro:property name="r_r_1_low" value="-0.25" />
  <xacro:property name="r_r_1_upp" value="0.4" />   

  <xacro:property name="l_2_low" value="0" />
  <xacro:property name="l_2_upp" value="0.5" />
  <xacro:property name="r_2_low" value="-0.5" />
  <xacro:property name="r_2_upp" value="0" />
  <xacro:property name="r_l_2_low" value="-0.15" />
  <xacro:property name="r_r_2_upp" value="0.15" />
  <xacro:property name="lr_3_low" value="0" />
  <xacro:property name="lr_3_upp" value="0.5" />

  <!-- rviz wont work with these xacros unless given as urdf

  <xacro:include filename="$(find ant_description)/urdf/ant_main_body.xacro"/>

  <xacro:include filename="$(find ant_description)/urdf/ant_leg_l_f.xacro" />

  <xacro:include filename="$(find ant_description)/urdf/ant_leg_r_f.xacro" /> -->

  <link name="base_link"/>

  <joint name="ant_attachment" type="fixed">
    <parent link="base_link"/>
    <child link="thorax"/>
    <origin xyz="0 0 0" rpy="0 0 0"/>
  </joint>

  <!-- thorax link -->
  <link name="thorax">
    <collision>
      <origin xyz="0.02495771 4.745264 0.9420236" rpy="0 0 0"/>
      <geometry>
        <mesh filename="package://ant_description/meshes/thorax.stl"/>
      </geometry>
    </collision>

    <visual>
      <origin xyz="0.02495771 4.745264 0.9420236" rpy="0 0 0"/>
      <geometry>
        <mesh filename="package://ant_description/meshes/thorax.stl"/>
      </geometry>
    </visual>

    <inertial>
      <origin xyz="-0.04847949 5.0895386 1.30014761" rpy="0 0 0"/>
      <mass value="40"/>
      <inertia
        ixx="2.1574865398e+02" 
        ixy="-1.5499513134e-01" 
        ixz="-4.3375096425e-02"
        iyy="5.3331719151e+01" 
        iyz="-1.7571679462e+01"
        izz="2.2341557491e+02"/>
    </inertial>
  </link> 

  <!-- head link -->
  <link name="head">
    <collision>
      <origin xyz="8.69815e-4 11.79549 -0.03817248" rpy="0 0 0"/>
      <geometry>
        <mesh filename="package://ant_description/meshes/head.stl"/>
      </geometry>
    </collision>

    <visual>
      <origin xyz="8.69815e-4 11.79549 -0.03817248" rpy="0 0 0"/>
      <geometry>
        <mesh filename="package://ant_description/meshes/head.stl"/>
      </geometry>
    </visual>

    <inertial>
      <origin xyz="0.001631625 11.33051132 0.00357429" rpy="0 0 0"/> 
      <mass value="30"/>
      <inertia
        ixx="6.1372709332e+01" 
        ixy="-2.4209532812e-02" 
        ixz="-2.7104785800e-04"
        iyy="6.3649281062e+01" 
        iyz="7.1256139380e+00"
        izz="8.1137643143e+01"/>
    </inertial>
  </link>  
  
  <joint name="thorax_head" type="fixed">
    <parent link="thorax"/>
    <child link="head"/>
  </joint>  

  <!-- petiole link -->
  <link name="petiole">
    <collision>
      <origin xyz="0.01740854 0.07322531 0.2697668" rpy="0 0 0"/>
      <geometry>
        <mesh filename="package://ant_description/meshes/petiole.stl"/>
      </geometry>
    </collision>

    <visual>
      <origin xyz="0.01740854 0.07322531 0.2697668" rpy="0 0 0"/>
      <geometry>
        <mesh filename="package://ant_description/meshes/petiole.stl"/>
      </geometry>
    </visual>

    <inertial>
      <origin xyz="0.00561879 0.00296973 0.28649062" rpy="0 0 0"/> 
      <mass value="5"/>
      <inertia
        ixx="2.7897944003e+00" 
        ixy="3.5781084256e-03" 
        ixz="-3.2402220006e-03"
        iyy="2.5550380430e+00" 
        iyz="-4.0086618959e-01"
        izz="2.0464923935e+00"/>
    </inertial>
  </link>  
  
  <joint name="thorax_petiole" type="fixed">
    <parent link="thorax"/>
    <child link="petiole"/>
  </joint> 

  <!-- node link --> 
  <link name="node">
    <collision>
      <origin xyz="-0.006898105 -1.105468 -0.2202131" rpy="0 0 0"/>
      <geometry>
        <mesh filename="package://ant_description/meshes/node.stl"/>
      </geometry>
    </collision>

    <visual>
      <origin xyz="-0.006898105 -1.105468 -0.2202131" rpy="0 0 0"/>
      <geometry>
        <mesh filename="package://ant_description/meshes/node.stl"/>
      </geometry>
    </visual>

    <inertial>
      <origin xyz="-0.011776415 -1.10854547 -0.22971905" rpy="0 0 0"/> 
      <mass value="2"/>
      <inertia
        ixx="3.5458615208e-01" 
        ixy="-4.6808282018e-04" 
        ixz="2.2591796230e-03"
        iyy="2.1462833835e-01" 
        iyz="-6.3565631669e-04"
        izz="3.8425372799e-01"/>
    </inertial>
  </link>  

  <joint name="petiole_node" type="fixed">
    <parent link="petiole"/>
    <child link="node"/>
  </joint> 

  <!-- gaster link --> 
  <link name="gaster">
    <collision>
      <origin xyz="-0.003080308 -4.342331 -1.633749" rpy="0 0 0"/>
      <geometry>
        <mesh filename="package://ant_description/meshes/gaster.stl"/>
      </geometry>
    </collision>

    <visual>
      <origin xyz="-0.003080308 -4.342331 -1.633749" rpy="0 0 0"/>
      <geometry>
        <mesh filename="package://ant_description/meshes/gaster.stl"/>
      </geometry>
    </visual>

    <inertial>
      <origin xyz="-0.007536868 -4.24358572 -1.27920505" rpy="0 0 0"/> 
      <mass value="35"/>  CHANGED to 35 from 50
      <inertia
        ixx="1.5049922562e+02" 
        ixy="3.3508063294e-03" 
        ixz="1.7003903286e-02"
        iyy="1.1459202296e+02" 
        iyz="-2.2113997039e+01"
        izz="1.5439307293e+02"/>
    </inertial>
  </link>  

  <joint name="node_gaster" type="fixed">
    <parent link="node"/>
    <child link="gaster"/>
  </joint>

  <!-- cox front left link -->
  <link name="cox_f_l">
    <collision>
      <origin xyz="-0.5 0 0" rpy="0 0 0"/>
      <geometry>
        <mesh filename="package://ant_description/meshes/cox_f_l.stl"/>
      </geometry>
    </collision>

    <visual>
      <origin xyz="-0.5 0 0" rpy="0 0 0"/>
      <geometry>
        <mesh filename="package://ant_description/meshes/cox_f_l.stl"/>
      </geometry>
    </visual>

    <inertial>
      <origin xyz="-0.48765049  1.6566350000e-02 -1.5535011000e-01" rpy="0 0 0"/> 
      <mass value="3"/>
      <inertia
        ixx="7.5768846297e-01" 
        ixy="1.7005788603e-01" 
        ixz="5.7852710942e-03"
        iyy="1.1727972097e+00" 
        iyz="5.6909853774e-02"
        izz="1.2224152912e+00"/>
    </inertial>
  </link>  

  <joint name="j_1_f_l" type="revolute">
    <parent link="thorax"/>
    <child link="cox_f_l"/>
    <origin xyz="-0.672313 5.942684 -0.2417362" rpy="0 0 0" />
    <axis xyz="0 0 1" />
    <limit effort="${j_eff}" velocity="${j_vel}" lower="${f_l_1_low}" upper="${f_l_1_upp}"/>
    <dynamics friction="500"/>  
  </joint>

  <!-- trochanter front left link -->
  <link name="trochanter_f_l">
    <collision>
      <origin xyz="-0.6 0 0" rpy="0 0 0"/>
      <geometry>
        <mesh filename="package://ant_description/meshes/trochanter_f_l.stl"/>
      </geometry>
    </collision>

    <visual>
      <origin xyz="-0.6 0 0" rpy="0 0 0"/>
      <geometry>
        <mesh filename="package://ant_description/meshes/trochanter_f_l.stl"/>
      </geometry>
    </visual>

    <inertial>
      <origin xyz="-0.77043483 -3.2823050000e-02  4.9396100000e-03" rpy="0 0 0"/> 
      <mass value="1"/>
      <inertia
        ixx="1.1496440267e-01" 
        ixy="3.4858491007e-02" 
        ixz="1.4360769641e-03"
        iyy="1.4220481517e-01" 
        iyz="-1.1846910889e-02"
        izz="1.5255737899e-01"/>
    </inertial>
  </link>  

  <joint name="j_2_f_l" type="revolute">
    <parent link="cox_f_l"/>
    <child link="trochanter_f_l"/>
    <origin xyz="-1.265769 0.454099 0.0176258" rpy="0 0 0" />
    <axis xyz="0 1 0" />
    <limit effort="${j_eff}" velocity="${j_vel}" lower="${l_2_low}" upper="${l_2_upp}"/>
    <dynamics friction="500"/> 
  </joint> 

  <!-- femur front left link -->
  <link name="femur_f_l">
    <collision>
      <origin xyz="-1.949923 1.783526 0.32062271" rpy="0 0 0"/>
      <geometry>
        <mesh filename="package://ant_description/meshes/femur_f_l.stl"/>
      </geometry>
    </collision>

    <visual>
      <origin xyz="-1.949923 1.783526 0.32062271" rpy="0 0 0"/>
      <geometry>
        <mesh filename="package://ant_description/meshes/femur_f_l.stl"/>
      </geometry>
    </visual>

    <inertial>
      <origin xyz="-0.5579356 -1.0128977000e-01  2.5225760000e-02" rpy="0 0 0"/> 
      <mass value="5"/>
      <inertia
        ixx="3.6197642457e+00" 
        ixy="2.1775364163e+00" 
        ixz="3.8242520797e-01"
        iyy="1.8778697845e+00" 
        iyz="-5.2415364462e-01"
        izz="5.0117853596e+00"/>
    </inertial>
  </link> 

  <joint name="trochanter_femur_f_l" type="fixed">
    <parent link="trochanter_f_l"/>
    <child link="femur_f_l"/>
  </joint>  

  <!-- tibia front left link -->
  <link name="tibia_f_l">
    <collision>
      <origin xyz="0 0 -1.3" rpy="0 0 -0.523599"/>
      <geometry>
        <mesh filename="package://ant_description/meshes/tibia_f_l.stl"/>
      </geometry>
    </collision>

    <visual>
      <origin xyz="0 0 -1.3" rpy="0 0 -0.523599"/>
      <geometry>
        <mesh filename="package://ant_description/meshes/tibia_f_l.stl"/>
      </geometry>
    </visual>
    
    <inertial>
      <origin xyz="-3.7722210000e-02 -6.1037620000e-02 -1.79721931" rpy="0 0 -0.523599"/> 
      <mass value="4"/>
      <inertia
        ixx="5.6769505167e+00" 
        ixy="-9.1392209980e-02" 
        ixz="-4.1384680225e-01"
        iyy="5.5128989027e+00" 
        iyz="-9.6529489518e-01"
        izz="3.8081446228e-01"/>
    </inertial> 
  </link>  

  <joint name="j_3_f_l" type="revolute">
    <parent link="femur_f_l"/>
    <child link="tibia_f_l"/>
    <origin xyz="-3.067233 2.99855 0.2249814" rpy="0 0 0.523599" />
    <limit effort="${j_eff}" velocity="${j_vel}" lower="${lr_3_low}" upper="${lr_3_upp}"/>
    <dynamics friction="500"/> 
  </joint> 

 <!-- tarsus front left link -->
  <link name="tarsus_f_l">
    <collision>
      <origin xyz="-1.164141 1.274724 -5.899937" rpy="0 0 -0.523599"/>
      <geometry>
        <mesh filename="package://ant_description/meshes/tarsus_f_l.stl"/>
      </geometry>
    </collision>

    <visual>
      <origin xyz="-1.164141 1.274724 -5.899937" rpy="0 0 -0.523599"/>
      <geometry>
        <mesh filename="package://ant_description/meshes/tarsus_f_l.stl"/>
      </geometry>
    </visual>

    <inertial>
      <origin xyz="0.197988 -0.332424 -0.92324425" rpy="0 0 -0.523599"/>
      <mass value="2"/>
      <inertia
        ixx="2.0383412574e+00" 
        ixy="5.0790120060e-01" 
        ixz="-1.2739759948e+00"
        iyy="2.7268712920e+00" 
        iyz="6.6243787205e-01"
        izz="1.2557246830e+00"/>
    </inertial>
  </link> 

  <joint name="tibia_tarsus_f_l" type="fixed">
    <parent link="tibia_f_l"/>
    <child link="tarsus_f_l"/>
  </joint>

  <!-- cox front right link -->
  <link name="cox_f_r">
    <collision>
      <origin xyz="0.5 0 0" rpy="0 0 0"/>
      <geometry>
        <mesh filename="package://ant_description/meshes/cox_f_r.stl"/>
      </geometry>
    </collision>

    <visual>
      <origin xyz="0.5 0 0" rpy="0 0 0"/>
      <geometry>
        <mesh filename="package://ant_description/meshes/cox_f_r.stl"/>
      </geometry>
    </visual>

    <inertial>
      <origin xyz="0.57905302  5.1128630000e-02 -1.3051884000e-01" rpy="0 0 0"/> 
      <mass value="3"/>
      <inertia
        ixx="7.5656651420e-01" 
        ixy="-1.6078972639e-01" 
        ixz="2.2975131314e-02"
        iyy="1.1275039835e+00" 
        iyz="5.7195192991e-02"
        izz="1.1844327222e+00"/>
    </inertial>
  </link>  

  <joint name="j_1_f_r" type="revolute">
    <parent link="thorax"/>
    <child link="cox_f_r"/>
    <origin xyz="0.69727071 5.942684 -0.2417362" rpy="0 0 0" />
    <axis xyz="0 0 1" />
    <limit effort="${j_eff}" velocity="${j_vel}" lower="${f_r_1_low}" upper="${f_r_1_upp}"/>
    <dynamics friction="500"/>  
  </joint>

  <!-- trochanter front right link -->
  <link name="trochanter_f_r">
    <collision>
      <origin xyz="0.6 0 0" rpy="0 0 0"/>
      <geometry>
        <mesh filename="package://ant_description/meshes/trochanter_f_r.stl"/>
      </geometry>
    </collision>

    <visual>
      <origin xyz="0.6 0 0" rpy="0 0 0"/>
      <geometry>
        <mesh filename="package://ant_description/meshes/trochanter_f_r.stl"/>
      </geometry>
    </visual>

    <inertial>
      <origin xyz="0.538491 -5.1388720000e-02 -1.3824200000e-02" rpy="0 0 0"/> 
      <mass value="1"/>
      <inertia
        ixx="1.0497057613e-01" 
        ixy="-3.6631126790e-02" 
        ixz="-3.9228430044e-03"
        iyy="1.4323023665e-01" 
        iyz="-2.1808929210e-02"
        izz="1.5518180277e-01"/>
    </inertial>
  </link>  

  <joint name="j_2_f_r" type="revolute">
    <parent link="cox_f_r"/>
    <child link="trochanter_f_r"/>
    <origin xyz="1.59727071 0.454099 0.0176258" rpy="0 0 0" />
    <axis xyz="0 1 0" />
    <limit effort="${j_eff}" velocity="${j_vel}" lower="${r_2_low}" upper="${r_2_upp}"/>
    <dynamics friction="500"/> 
  </joint> 

  <!-- femur front right link -->
  <link name="femur_f_r">
    <collision>
      <origin xyz="1.949923 1.783526 0.32062271" rpy="0 0 0"/>
      <geometry>
        <mesh filename="package://ant_description/meshes/femur_f_r.stl"/>
      </geometry>
    </collision>

    <visual>
      <origin xyz="1.949923 1.783526 0.32062271" rpy="0 0 0"/>
      <geometry>
        <mesh filename="package://ant_description/meshes/femur_f_r.stl"/>
      </geometry>
    </visual>

    <inertial>
      <origin xyz="0.58560998 -5.2536510000e-02  3.3790940000e-02" rpy="0 0 0"/> 
      <mass value="5"/>
      <inertia
        ixx="3.5605818097e+00" 
        ixy="-2.1346250176e+00" 
        ixz="-4.1254699156e-01"
        iyy="1.8632358937e+00" 
        iyz="-5.6765821955e-01"
        izz="4.9254199566e+00"/>
    </inertial>
  </link> 

  <joint name="trochanter_femur_f_r" type="fixed">
    <parent link="trochanter_f_r"/>
    <child link="femur_f_r"/>
  </joint>  

  <!-- tibia front right link -->
  <link name="tibia_f_r">
    <collision>
      <origin xyz="0 0 -1.3" rpy="0 0 0.523599"/>
      <geometry>
        <mesh filename="package://ant_description/meshes/tibia_f_r.stl"/>
      </geometry>
    </collision>

    <visual>
      <origin xyz="0 0 -1.3" rpy="0 0 0.523599"/>
      <geometry>
        <mesh filename="package://ant_description/meshes/tibia_f_r.stl"/>
      </geometry>
    </visual>

    <inertial>
      <origin xyz="4.1651520000e-02 -5.6355840000e-02 -1.77705898" rpy="0 0 0.523599"/> 
      <mass value="4"/>
      <inertia
        ixx="5.5697936408e+00" 
        ixy="8.9994538190e-02" 
        ixz="4.0634984476e-01"
        iyy="5.4089508408e+00" 
        iyz="-9.4506940495e-01"
        izz="3.7695625536e-01"/>
    </inertial>
  </link>  

  <joint name="j_3_f_r" type="revolute">
    <parent link="femur_f_r"/>
    <child link="tibia_f_r"/>
    <origin xyz="3.067233 2.99855 0.2249814" rpy="0 0 -0.523599" />
    <axis xyz="1 0 0" />
    <limit effort="${j_eff}" velocity="${j_vel}" lower="${lr_3_low}" upper="${lr_3_upp}"/>
    <dynamics friction="500"/> 
  </joint> 

 <!-- tarsus front right link -->
  <link name="tarsus_f_r">
    <collision>
      <origin xyz="1.164141 1.274724 -5.899937" rpy="0 0 0.523599"/>
      <geometry>
        <mesh filename="package://ant_description/meshes/tarsus_f_r.stl"/>
      </geometry>
    </collision>

    <visual>
      <origin xyz="1.164141 1.274724 -5.899937" rpy="0 0 0.523599"/>
      <geometry>
        <mesh filename="package://ant_description/meshes/tarsus_f_r.stl"/>
      </geometry>
    </visual>

    <inertial>
      <origin xyz="-0.201113 -0.34006 -0.916733" rpy="0 0 0.523599"/>
      <mass value="2"/>
      <inertia
        ixx="2.0264224199e+00" 
        ixy="-5.0324785226e-01" 
        ixz="1.2654551473e+00"
        iyy="2.7097661696e+00" 
        iyz="6.5752556549e-01"
        izz="1.2447538164e+00"/>
    </inertial>
  </link> 

  <joint name="tibia_tarsus_f_r" type="fixed">
    <parent link="tibia_f_r"/>
    <child link="tarsus_f_r"/>
  </joint> 

  <!-- cox middle left link -->
  <link name="cox_m_l">
    <collision>
      <origin xyz="-0.5 0 0" rpy="0 0 0"/>
      <geometry>
        <mesh filename="package://ant_description/meshes/cox_m_l.stl"/>
      </geometry>
    </collision>

    <visual>
      <origin xyz="-0.5 0 0" rpy="0 0 0"/>
      <geometry>
        <mesh filename="package://ant_description/meshes/cox_m_l.stl"/>
      </geometry>
    </visual>

    <inertial>
      <origin xyz="-0.51716983  1.1915810000e-02 -1.3921484000e-01" rpy="0 0 0"/> 
      <mass value="3"/>
      <inertia
        ixx="7.8260573866e-01" 
        ixy="-1.9846590636e-01" 
        ixz="-2.0231143554e-03"
        iyy="1.1383764760e+00" 
        iyz="6.4265649619e-02"
        izz="1.2384929781e+00"/>
    </inertial>
  </link>  

  <joint name="j_1_m_l" type="revolute">
    <parent link="thorax"/>
    <child link="cox_m_l"/>
    <origin xyz="-0.87320329 3.654325 -0.04402315" rpy="0 0 0" />
    <axis xyz="0 0 1" />
    <limit effort="${j_eff}" velocity="${j_vel}" lower="${m_l_1_low}" upper="${m_l_1_upp}"/>
    <dynamics friction="500"/>  
  </joint>

  <!-- trochanter middle left link -->
  <link name="trochanter_m_l">
    <collision>
      <origin xyz="-0.6 0 0" rpy="0 0 0"/>
      <geometry>
        <mesh filename="package://ant_description/meshes/trochanter_m_l.stl"/>
      </geometry>
    </collision>

    <visual>
      <origin xyz="-0.6 0 0" rpy="0 0 0"/>
      <geometry>
        <mesh filename="package://ant_description/meshes/trochanter_m_l.stl"/>
      </geometry>
    </visual>

    <inertial>
      <origin xyz="-0.55512966  1.4158560000e-02 -7.3947500000e-03" rpy="0 0 0"/> 
      <mass value="1"/>
      <inertia
        ixx="1.1101995697e-01" 
        ixy="-3.3613121204e-02" 
        ixz="1.1913985257e-02"
        iyy="1.4858710622e-01" 
        iyz="-4.0038853935e-03"
        izz="1.5366513364e-01"/>
    </inertial>
  </link>  

  <joint name="j_2_m_l" type="revolute">
    <parent link="cox_m_l"/>
    <child link="trochanter_m_l"/>
    <origin xyz="-1.092786 -0.667436 0.15847855" rpy="0 0 0" />
    <axis xyz="0 1 0" />
    <limit effort="${j_eff}" velocity="${j_vel}" lower="${l_2_low}" upper="${l_2_upp}"/>
    <dynamics friction="500"/> 
  </joint> 

  <!-- femur middle left link -->
  <link name="femur_m_l">
    <collision>
      <origin xyz="-3.031796 -1.037177 0.5874824" rpy="0 0 0"/>
      <geometry>
        <mesh filename="package://ant_description/meshes/femur_m_l.stl"/>
      </geometry>
    </collision>

    <visual>
      <origin xyz="-3.031796 -1.037177 0.5874824" rpy="0 0 0"/>
      <geometry>
        <mesh filename="package://ant_description/meshes/femur_m_l.stl"/>
      </geometry>
    </visual>

    <inertial>
      <origin xyz="-0.28026106 1.1244939000e-01 -6.3924120000e-02" rpy="0 0 0"/> 
      <mass value="5"/>
      <inertia
        ixx="1.5111447845e+00" 
        ixy="-2.2827053904e+00" 
        ixz="1.2224953298e+00"
        iyy="6.0794410410e+00" 
        iyz="5.2271625542e-01"
        izz="6.7716874529e+00"/>
    </inertial>
  </link> 

  <joint name="trochanter_femur_m_l" type="fixed">
    <parent link="trochanter_m_l"/>
    <child link="femur_m_l"/>
  </joint>

  <!-- tibia middle left link -->
  <link name="tibia_m_l">
    <collision>
      <origin xyz="0.136808 0.375877 -1.3" rpy="0 0 -1.91986"/>
      <geometry>
        <mesh filename="package://ant_description/meshes/tibia_m_l.stl"/>
      </geometry>
    </collision>

    <visual>
      <origin xyz="0.136808 0.375877 -1.3" rpy="0 0 -1.91986"/>
      <geometry>
        <mesh filename="package://ant_description/meshes/tibia_m_l.stl"/>
      </geometry>
    </visual>
    
    <inertial>
      <origin xyz="0.122652 0.593339 -1.79632004" rpy="0 0 -1.91986"/> 
      <mass value="4"/>
      <inertia
        ixx="5.1136973632e+00" 
        ixy="-2.1964789642e-01" 
        ixz="-1.5570160091e+00"
        iyy="5.5119473180e+00" 
        iyz="-7.4216810283e-01"
        izz="7.9706175728e-01"/>
    </inertial> 
  </link>  

  <joint name="j_3_m_l" type="revolute">
    <parent link="femur_m_l"/>
    <child link="tibia_m_l"/>
    <origin xyz="-4.794432 -1.923477 0.8121009" rpy="0 0 1.91986" />
    <axis xyz="1 0 0" />
    <limit effort="${j_eff}" velocity="${j_vel}" lower="${lr_3_low}" upper="${lr_3_upp}"/>
    <dynamics friction="500"/> 
  </joint> 

 <!-- tarsus middle left link TODO repair mesh and inertia -->
  <link name="tarsus_m_l">
    <collision>
      <origin xyz="0.556888 1.563018 -6.5016463" rpy="0 0 -1.91986"/>
      <geometry>
        <mesh filename="package://ant_description/meshes/tarsus_m_l.stl"/>
      </geometry>
    </collision>

    <visual>
      <origin xyz="0.556888 1.563018 -6.5016463" rpy="0 0 -1.91986"/>
      <geometry>
        <mesh filename="package://ant_description/meshes/tarsus_m_l.stl"/>
      </geometry>
    </visual>

    <!--<inertial>
      <origin xyz="0.197988 -0.332424 -0.92324425" rpy="0 0 -1.91986"/>
      <mass value="2"/>
      <inertia
        ixx="2.6814907591e+00" 
        ixy="3.5543530919e-02" 
        ixz="-4.3935904718e-01"
        iyy="2.7333997515e+00" 
        iyz="2.4487690192e-01"
        izz="1.3475215922e-01"/>
    </inertial> -->
  </link> 

  <joint name="tibia_tarsus_m_l" type="fixed">
    <parent link="tibia_m_l"/>
    <child link="tarsus_m_l"/>
  </joint>

  <!-- cox middle right link -->
  <link name="cox_m_r">
    <collision>
      <origin xyz="0.5 0 0" rpy="0 0 0"/>
      <geometry>
        <mesh filename="package://ant_description/meshes/cox_m_r.stl"/>
      </geometry>
    </collision>

    <visual>
      <origin xyz="0.5 0 0" rpy="0 0 0"/>
      <geometry>
        <mesh filename="package://ant_description/meshes/cox_m_r.stl"/>
      </geometry>
    </visual>

    <inertial>
      <origin xyz="0.51717  1.1915810000e-02 -1.3921484000e-01" rpy="0 0 0"/> 
      <mass value="3"/>
      <inertia
        ixx="7.8260573866e-01" 
        ixy="1.9846590636e-01" 
        ixz="2.0231143554e-03"
        iyy="1.1383764760e+00" 
        iyz="6.4265649619e-02"
        izz="1.2384929781e+00"/>
    </inertial>
  </link>  

  <joint name="j_1_m_r" type="revolute">
    <parent link="thorax"/>
    <child link="cox_m_r"/>
    <origin xyz="0.87320329 3.654325 -0.04402315" rpy="0 0 0" />
    <axis xyz="0 0 1" />
    <limit effort="${j_eff}" velocity="${j_vel}" lower="${m_r_1_low}" upper="${m_r_1_upp}"/>
    <dynamics friction="500"/>  
  </joint>

  <!-- trochanter middle right link -->
  <link name="trochanter_m_r">
    <collision>
      <origin xyz="0.6 0 0" rpy="0 0 0"/>
      <geometry>
        <mesh filename="package://ant_description/meshes/trochanter_m_r.stl"/>
      </geometry>
    </collision>

    <visual>
      <origin xyz="0.6 0 0" rpy="0 0 0"/>
      <geometry>
        <mesh filename="package://ant_description/meshes/trochanter_m_r.stl"/>
      </geometry>
    </visual>

    <inertial>
      <origin xyz="0.54487034  1.4158560000e-02 -7.3947500000e-03" rpy="0 0 0"/> 
      <mass value="1"/>
      <inertia
        ixx="1.1102254555e-01" 
        ixy="3.3611787480e-02" 
        ixz="-1.1913985257e-02"
        iyy="1.4858710622e-01" 
        iyz="-4.0038853935e-03"
        izz="1.5366513364e-01"/>
    </inertial>
  </link>  

  <joint name="j_2_m_r" type="revolute">
    <parent link="cox_m_r"/>
    <child link="trochanter_m_r"/>
    <origin xyz="1.092786 -0.667436 0.15847855" rpy="0 0 0" />
    <axis xyz="0 1 0" />
    <limit effort="${j_eff}" velocity="${j_vel}" lower="${r_2_low}" upper="${r_2_upp}"/>
    <dynamics friction="500"/> 
  </joint> 

  <!-- femur middle right link -->
  <link name="femur_m_r">
    <collision>
      <origin xyz="3.031796 -1.037177 0.5874824" rpy="0 0 0"/>
      <geometry>
        <mesh filename="package://ant_description/meshes/femur_m_r.stl"/>
      </geometry>
    </collision>

    <visual>
      <origin xyz="3.031796 -1.037177 0.5874824" rpy="0 0 0"/>
      <geometry>
        <mesh filename="package://ant_description/meshes/femur_m_r.stl"/>
      </geometry>
    </visual>

    <inertial>
      <origin xyz="0.28026106 1.1244939000e-01 -6.3924120000e-02" rpy="0 0 0"/> 
      <mass value="5"/>
      <inertia
        ixx="1.5162198048e+00" 
        ixy="2.2819992907e+00" 
        ixz="-1.2230956433e+00"
        iyy="6.0647092751e+00" 
        iyz="5.2541112821e-01"
        izz="6.7587161883e+00"/>
    </inertial>
  </link> 

  <joint name="trochanter_femur_m_r" type="fixed">
    <parent link="trochanter_m_r"/>
    <child link="femur_m_r"/>
  </joint>

  <!-- tibia middle right link -->
  <link name="tibia_m_r">
    <collision>
      <origin xyz="-0.136808 0.375877 -1.3" rpy="0 0 1.91986"/>
      <geometry>
        <mesh filename="package://ant_description/meshes/tibia_m_r.stl"/>
      </geometry>
    </collision>

    <visual>
      <origin xyz="-0.136808 0.375877 -1.3" rpy="0 0 1.91986"/>
      <geometry>
        <mesh filename="package://ant_description/meshes/tibia_m_r.stl"/>
      </geometry>
    </visual>
    
    <inertial>
      <origin xyz="-0.122652 0.593339 -1.79632004" rpy="0 0 1.91986"/> 
      <mass value="4"/>
      <inertia
        ixx="5.1136973632e+00" 
        ixy="2.1964789642e-01" 
        ixz="1.5570160091e+00"
        iyy="5.5119473180e+00" 
        iyz="-7.4216810283e-01"
        izz="7.9706175728e-01"/>
    </inertial> 
  </link>  

  <joint name="j_3_m_r" type="revolute">
    <parent link="femur_m_r"/>
    <child link="tibia_m_r"/>
    <origin xyz="4.794432 -1.923477 0.8121009" rpy="0 0 -1.91986" />
    <axis xyz="1 0 0" />
    <limit effort="${j_eff}" velocity="${j_vel}" lower="${lr_3_low}" upper="${lr_3_upp}"/>
    <dynamics friction="500"/> 
  </joint> 

 <!-- tarsus middle rightt link TODO repair mesh and inertia -->
  <link name="tarsus_m_r">
    <collision>
      <origin xyz="-0.556888 1.563018 -6.5016463" rpy="0 0 1.91986"/>
      <geometry>
        <mesh filename="package://ant_description/meshes/tarsus_m_r.stl"/>
      </geometry>
    </collision>

    <visual>
      <origin xyz="-0.556888 1.563018 -6.5016463" rpy="0 0 1.91986"/>
      <geometry>
        <mesh filename="package://ant_description/meshes/tarsus_m_r.stl"/>
      </geometry>
    </visual>

    <!--<inertial>
      <origin xyz="0.197988 -0.332424 -0.92324425" rpy="0 0 -1.91986"/>
      <mass value="2"/>
      <inertia
        ixx="2.6814907591e+00" 
        ixy="3.5543530919e-02" 
        ixz="-4.3935904718e-01"
        iyy="2.7333997515e+00" 
        iyz="2.4487690192e-01"
        izz="1.3475215922e-01"/>
    </inertial> -->
  </link> 

  <joint name="tibia_tarsus_m_r" type="fixed">
    <parent link="tibia_m_r"/>
    <child link="tarsus_m_r"/>
  </joint>

  <!-- cox rear left link -->
  <link name="cox_r_l">
    <collision>
      <origin xyz="-0.5 -0.5 0" rpy="0 0 0"/>
      <geometry>
        <mesh filename="package://ant_description/meshes/cox_r_l.stl"/>
      </geometry>
    </collision>

    <visual>
      <origin xyz="-0.5 -0.5 0" rpy="0 0 0"/>
      <geometry>
        <mesh filename="package://ant_description/meshes/cox_r_l.stl"/>
      </geometry>
    </visual>

    <inertial>
      <origin xyz="-0.54993608 -0.55808213 -1.8706305000e-01" rpy="0 0 0"/> 
      <mass value="3"/>
      <inertia
        ixx="9.7279348468e-01" 
        ixy="-2.4893216773e-01" 
        ixz="-4.3977186027e-02"
        iyy="8.8979866554e-01" 
        iyz="3.9916256869e-02"
        izz="1.1924646641e+00"/>
    </inertial>
  </link>  

  <joint name="j_1_r_l" type="revolute">
    <parent link="thorax"/>
    <child link="cox_r_l"/>
    <origin xyz="-1.004655 2.310507 -0.4687623 " rpy="0 0 0" />
    <axis xyz="0 0 1" />
    <limit effort="${j_eff}" velocity="${j_vel}" lower="${r_l_1_low}" upper="${r_l_1_upp}"/>
    <dynamics friction="500"/>  
  </joint>

  <!-- trochanter rear left link -->
  <link name="trochanter_r_l">
    <collision>
      <origin xyz="-0.5 0 0" rpy="0 0 0"/>
      <geometry>
        <mesh filename="package://ant_description/meshes/trochanter_r_l.stl"/>
      </geometry>
    </collision>

    <visual>
      <origin xyz="-0.5 0 0" rpy="0 0 0"/>
      <geometry>
        <mesh filename="package://ant_description/meshes/trochanter_r_l.stl"/>
      </geometry>
    </visual>

    <inertial>
      <origin xyz="-0.42571826  1.0669486000e-01 -3.1070070000e-02" rpy="0 0 0"/> 
      <mass value="1"/>
      <inertia
        ixx="1.5073148763e-01" 
        ixy="-3.8447467658e-02" 
        ixz="1.2660324006e-02"
        iyy="1.2943070910e-01" 
        iyz="3.4239571588e-04"
        izz="1.6587704941e-01"/>
    </inertial>
  </link> 

  <joint name="j_2_r_l" type="revolute">
    <parent link="cox_r_l"/>
    <child link="trochanter_r_l"/>
    <origin xyz="-0.955945 -1.6218341 0.1198297" rpy="0 0 0" />
    <axis xyz="0 1 0" />
    <limit effort="${j_eff}" velocity="${j_vel}" lower="${r_l_2_low}" upper="${l_2_upp}"/>
    <dynamics friction="500"/>
  </joint> 

  <!-- femur rear left link -->
  <link name="femur_r_l">
    <collision>
      <origin xyz="-2.97037 -2.4887559 0.8584707" rpy="0 0 0"/>
      <geometry>
        <mesh filename="package://ant_description/meshes/femur_r_l.stl"/>
      </geometry>
    </collision>

    <visual>
      <origin xyz="-2.97037 -2.4887559 0.8584707" rpy="0 0 0"/>
      <geometry>
        <mesh filename="package://ant_description/meshes/femur_r_l.stl"/>
      </geometry>
    </visual>

    <inertial>
      <origin xyz="-0.04229401  5.9847164000e-01 -1.0237488000e-01" rpy="0 0 0"/> 
      <mass value="5"/>
      <inertia
        ixx="6.5537052690e+00" 
        ixy="-5.7615418246e+00" 
        ixz="1.7949193563e+00"
        iyy="6.7640416562e+00" 
        iyz="1.7889461762e+00"
        izz="1.1794042420e+01"/>
    </inertial>
  </link> 

  <joint name="trochanter_femur_r_l" type="fixed">
    <parent link="trochanter_r_l"/>
    <child link="femur_r_l"/>
  </joint>

  <!-- tibia rear left link -->
  <link name="tibia_r_l">
    <collision>
      <origin xyz="0 0 -1.6" rpy="0 0 -2.44346"/>
      <geometry>
        <mesh filename="package://ant_description/meshes/tibia_r_l.stl"/>
      </geometry>
    </collision>

    <visual>
      <origin xyz="0 0 -1.6" rpy="0 0 -2.44346"/>
      <geometry>
        <mesh filename="package://ant_description/meshes/tibia_r_l.stl"/>
      </geometry>
    </visual>
    
    <inertial>
      <origin xyz="0.00756 0.24018 -1.90939386" rpy="0 0 -2.44346"/> 
      <mass value="4"/>
      <inertia
        ixx="7.7173053799e+00" 
        ixy="-5.2599828689e-02" 
        ixz="-1.9881656369e-01"
        iyy="7.2343761778e+00" 
        iyz="-1.9348606907e+00"
        izz="7.2286763244e-01"/>
    </inertial> 
  </link>  

  <joint name="j_3_r_l" type="revolute">
    <parent link="femur_r_l"/>
    <child link="tibia_r_l"/>
    <origin xyz="-4.81788 -4.9756749 1.1238474" rpy="0 0 2.44346" />
    <axis xyz="1 0 0" />
    <limit effort="${j_eff}" velocity="${j_vel}" lower="${lr_3_low}" upper="${lr_3_upp}"/>
    <dynamics friction="500"/> 
  </joint> 

 <!-- tarsus rear left link -->
  <link name="tarsus_r_l">
    <collision>
      <origin xyz="-1.452104 1.655428 -5.6634428" rpy="0 0 -2.44346"/>
      <geometry>
        <mesh filename="package://ant_description/meshes/tarsus_r_l.stl"/>
      </geometry>
    </collision>

    <visual>
      <origin xyz="-1.452104 1.655428 -5.6634428" rpy="0 0 -2.44346"/>
      <geometry>
        <mesh filename="package://ant_description/meshes/tarsus_r_l.stl"/>
      </geometry>
    </visual>

    <inertial>
      <origin xyz="5.2596670000e-02 -3.5839279000e-01 -1.60963057" rpy="0 0 -2.44346"/>
      <mass value="2"/>
      <inertia
        ixx="3.3858868805e+00" 
        ixy="7.6075774747e-02" 
        ixz="9.0168570414e-02"
        iyy="1.9667853495e+00" 
        iyz="-1.6554334105e+00"
        izz="1.4653702460e+00"/>
    </inertial>
  </link> 

  <joint name="tibia_tarsus_r_l" type="fixed">
    <parent link="tibia_r_l"/>
    <child link="tarsus_r_l"/>
  </joint>

  <!-- cox rear right link -->
  <link name="cox_r_r">
    <collision>
      <origin xyz="0.5 -0.5 0" rpy="0 0 0"/>
      <geometry>
        <mesh filename="package://ant_description/meshes/cox_r_r.stl"/>
      </geometry>
    </collision>

    <visual>
      <origin xyz="0.5 -0.5 0" rpy="0 0 0"/>
      <geometry>
        <mesh filename="package://ant_description/meshes/cox_r_r.stl"/>
      </geometry>
    </visual>

    <inertial>
      <origin xyz="0.5558994 -0.58611938 -1.8706305000e-01" rpy="0 0 0"/> 
      <mass value="3"/>
      <inertia
        ixx="9.7229680289e-01" 
        ixy="2.5368497826e-01" 
        ixz="4.4356865489e-02"
        iyy="8.9010367126e-01" 
        iyz="3.1340777388e-02"
        izz="1.2001971705e+00"/>
    </inertial>
  </link>  

  <joint name="j_1_r_r" type="revolute">
    <parent link="thorax"/>
    <child link="cox_r_r"/>
    <origin xyz="0.996461 2.346683 -0.5018439" rpy="0 0 0" />
    <axis xyz="0 0 1" />
    <limit effort="${j_eff}" velocity="${j_vel}" lower="${r_r_1_low}" upper="${r_r_1_upp}"/>
    <dynamics friction="500"/>  
  </joint>

  <!-- trochanter rear right link -->
  <link name="trochanter_r_r">
    <collision>
      <origin xyz="0.5 0 0" rpy="0 0 0"/>
      <geometry>
        <mesh filename="package://ant_description/meshes/trochanter_r_r.stl"/>
      </geometry>
    </collision>

    <visual>
      <origin xyz="0.5 0 0" rpy="0 0 0"/>
      <geometry>
        <mesh filename="package://ant_description/meshes/trochanter_r_r.stl"/>
      </geometry>
    </visual>

    <inertial>
      <origin xyz="0.42571826  1.0669486000e-01 -3.1070070000e-02" rpy="0 0 0"/> 
      <mass value="1"/>
      <inertia
        ixx="1.5073148763e-01" 
        ixy="3.8447467658e-02" 
        ixz="-1.2660324006e-02"
        iyy="1.2943070910e-01" 
        iyz="3.4239571588e-04"
        izz="1.6587704941e-01"/>
    </inertial>
  </link> 

  <joint name="j_2_r_r" type="revolute">
    <parent link="cox_r_r"/>
    <child link="trochanter_r_r"/>
    <origin xyz="0.955945 -1.6218341 0.1198297" rpy="0 0 0" />
    <axis xyz="0 1 0" />
    <limit effort="${j_eff}" velocity="${j_vel}" lower="${r_2_low}" upper="${r_r_2_upp}"/>
    <dynamics friction="500"/>
  </joint> 

  <!-- femur rear right link -->
  <link name="femur_r_r">
    <collision>
      <origin xyz="2.97037 -2.4887559 0.8584707" rpy="0 0 0"/>
      <geometry>
        <mesh filename="package://ant_description/meshes/femur_r_r.stl"/>
      </geometry>
    </collision>

    <visual>
      <origin xyz="2.97037 -2.4887559 0.8584707" rpy="0 0 0"/>
      <geometry>
        <mesh filename="package://ant_description/meshes/femur_r_r.stl"/>
      </geometry>
    </visual>

    <inertial>
      <origin xyz="0.04229401  5.9847164000e-01 -1.0237488000e-01" rpy="0 0 0"/> 
      <mass value="5"/>
      <inertia
        ixx="6.5537052690e+00" 
        ixy="5.7615418246e+00" 
        ixz="-1.7949193563e+00"
        iyy="6.7640416562e+00" 
        iyz="1.7889461762e+00"
        izz="1.1794042420e+01"/>
    </inertial>
  </link> 

  <joint name="trochanter_femur_r_r" type="fixed">
    <parent link="trochanter_r_r"/>
    <child link="femur_r_r"/>
  </joint>

  <!-- tibia rear right link -->
  <link name="tibia_r_r">
    <collision>
      <origin xyz="0 0 -1.6" rpy="0 0 2.44346"/>
      <geometry>
        <mesh filename="package://ant_description/meshes/tibia_r_r.stl"/>
      </geometry>
    </collision>

    <visual>
      <origin xyz="0 0 -1.6" rpy="0 0 2.44346"/>
      <geometry>
        <mesh filename="package://ant_description/meshes/tibia_r_r.stl"/>
      </geometry>
    </visual>
    
    <inertial>
      <origin xyz="-0.00756 0.24018 -1.90939386" rpy="0 0 2.44346"/> 
      <mass value="4"/>
      <inertia
        ixx="7.7173053799e+00" 
        ixy="5.2599828689e-02" 
        ixz="1.9881656369e-01"
        iyy="7.2343761778e+00" 
        iyz="-1.9348606907e+00"
        izz="7.2286763244e-01"/>
    </inertial> 
  </link>  

  <joint name="j_3_r_r" type="revolute">
    <parent link="femur_r_r"/>
    <child link="tibia_r_r"/>
    <origin xyz="4.81788 -4.9756749 1.1238474" rpy="0 0 -2.44346" />
    <axis xyz="1 0 0" />
    <limit effort="${j_eff}" velocity="${j_vel}" lower="${lr_3_low}" upper="${lr_3_upp}"/>
    <dynamics friction="500"/> 
  </joint> 

 <!-- tarsus rear right link -->
  <link name="tarsus_r_r">
    <collision>
      <origin xyz="1.452104 1.655428 -5.6634428" rpy="0 0 2.44346"/>
      <geometry>
        <mesh filename="package://ant_description/meshes/tarsus_r_r.stl"/>
      </geometry>
    </collision>

    <visual>
      <origin xyz="1.452104 1.655428 -5.6634428" rpy="0 0 2.44346"/>
      <geometry>
        <mesh filename="package://ant_description/meshes/tarsus_r_r.stl"/>
      </geometry>
    </visual>

    <inertial>
      <origin xyz="-5.2596670000e-02 -3.5839279000e-01 -1.60963057" rpy="0 0 2.44346"/>
      <mass value="2"/>
      <inertia
        ixx="3.3858868805e+00" 
        ixy="7.6075774747e-02" 
        ixz="9.0168570414e-02"
        iyy="1.9667853495e+00" 
        iyz="-1.6554334105e+00"
        izz="1.4653702460e+00"/>
    </inertial>
  </link> 

  <joint name="tibia_tarsus_r_r" type="fixed">
    <parent link="tibia_r_r"/>
    <child link="tarsus_r_r"/>
  </joint>




  <transmission name="transm_f_l_1">
    <type>transmission_interface/SimpleTransmission</type>
    <joint name="j_1_f_l">
      <hardwareInterface>hardware_interface/EffortJointInterface</hardwareInterface>    
    </joint>
    <actuator name="m_f_l_1">
      <hardwareInterface>hardware_interface/EffortJointInterface</hardwareInterface>
      <mechanicalReduction>1</mechanicalReduction>
    </actuator>
  </transmission>

  <transmission name="transm_f_l_2">
    <type>transmission_interface/SimpleTransmission</type>
    <joint name="j_2_f_l">
      <hardwareInterface>hardware_interface/EffortJointInterface</hardwareInterface>    
    </joint>
    <actuator name="m_f_l_2">
      <hardwareInterface>hardware_interface/EffortJointInterface</hardwareInterface>
      <mechanicalReduction>1</mechanicalReduction>
    </actuator>
  </transmission>

  <transmission name="transm_f_l_3">
    <type>transmission_interface/SimpleTransmission</type>
    <joint name="j_3_f_l">
      <hardwareInterface>hardware_interface/EffortJointInterface</hardwareInterface>    
    </joint>
    <actuator name="m_f_l_3">
      <hardwareInterface>hardware_interface/EffortJointInterface</hardwareInterface>
      <mechanicalReduction>1</mechanicalReduction>
    </actuator>
  </transmission>  

  <transmission name="transm_f_r_1">
    <type>transmission_interface/SimpleTransmission</type>
    <joint name="j_1_f_r">
      <hardwareInterface>hardware_interface/EffortJointInterface</hardwareInterface>    
    </joint>
    <actuator name="m_f_r_1">
      <hardwareInterface>hardware_interface/EffortJointInterface</hardwareInterface>
      <mechanicalReduction>1</mechanicalReduction>
    </actuator>
  </transmission>

  <transmission name="transm_f_r_2">
    <type>transmission_interface/SimpleTransmission</type>
    <joint name="j_2_f_r">
      <hardwareInterface>hardware_interface/EffortJointInterface</hardwareInterface>    
    </joint>
    <actuator name="m_f_r_2">
      <hardwareInterface>hardware_interface/EffortJointInterface</hardwareInterface>
      <mechanicalReduction>1</mechanicalReduction>
    </actuator>
  </transmission>

  <transmission name="transm_f_r_3">
    <type>transmission_interface/SimpleTransmission</type>
    <joint name="j_3_f_r">
      <hardwareInterface>hardware_interface/EffortJointInterface</hardwareInterface>    
    </joint>
    <actuator name="m_f_r_3">
      <hardwareInterface>hardware_interface/EffortJointInterface</hardwareInterface>
      <mechanicalReduction>1</mechanicalReduction>
    </actuator>
  </transmission> 

  <transmission name="transm_m_l_1">
    <type>transmission_interface/SimpleTransmission</type>
    <joint name="j_1_m_l">
      <hardwareInterface>hardware_interface/EffortJointInterface</hardwareInterface>    
    </joint>
    <actuator name="m_m_l_1">
      <hardwareInterface>hardware_interface/EffortJointInterface</hardwareInterface>
      <mechanicalReduction>1</mechanicalReduction>
    </actuator>
  </transmission>

  <transmission name="transm_m_l_2">
    <type>transmission_interface/SimpleTransmission</type>
    <joint name="j_2_m_l">
      <hardwareInterface>hardware_interface/EffortJointInterface</hardwareInterface>   
    </joint>
    <actuator name="m_m_l_2">
      <hardwareInterface>hardware_interface/EffortJointInterface</hardwareInterface>
      <mechanicalReduction>1</mechanicalReduction>
    </actuator>
  </transmission>

  <transmission name="transm_m_l_3">
    <type>transmission_interface/SimpleTransmission</type>
    <joint name="j_3_m_l">
      <hardwareInterface>hardware_interface/EffortJointInterface</hardwareInterface>    
    </joint>
    <actuator name="m_m_l_3">
      <hardwareInterface>hardware_interface/EffortJointInterface</hardwareInterface>
      <mechanicalReduction>1</mechanicalReduction>
    </actuator>
  </transmission> 

  <transmission name="transm_m_r_1">
    <type>transmission_interface/SimpleTransmission</type>
    <joint name="j_1_m_r">
      <hardwareInterface>hardware_interface/EffortJointInterface</hardwareInterface>    
    </joint>
    <actuator name="m_m_l_r">
      <hardwareInterface>hardware_interface/EffortJointInterface</hardwareInterface>
      <mechanicalReduction>1</mechanicalReduction>
    </actuator>
  </transmission>

  <transmission name="transm_m_r_2">
    <type>transmission_interface/SimpleTransmission</type>
    <joint name="j_2_m_r">
      <hardwareInterface>hardware_interface/EffortJointInterface</hardwareInterface>    
    </joint>
    <actuator name="m_m_r_2">
      <hardwareInterface>hardware_interface/EffortJointInterface</hardwareInterface>
      <mechanicalReduction>1</mechanicalReduction>
    </actuator>
  </transmission>

  <transmission name="transm_m_r_3">
    <type>transmission_interface/SimpleTransmission</type>
    <joint name="j_3_m_r">
      <hardwareInterface>hardware_interface/EffortJointInterface</hardwareInterface>    
    </joint>
    <actuator name="m_m_r_3">
      <hardwareInterface>hardware_interface/EffortJointInterface</hardwareInterface>
      <mechanicalReduction>1</mechanicalReduction>
    </actuator>
  </transmission> 

  <transmission name="transm_r_l_1">
    <type>transmission_interface/SimpleTransmission</type>
    <joint name="j_1_r_l">
      <hardwareInterface>hardware_interface/EffortJointInterface</hardwareInterface>    
    </joint>
    <actuator name="m_r_l_1">
      <hardwareInterface>hardware_interface/EffortJointInterface</hardwareInterface>
      <mechanicalReduction>1</mechanicalReduction>
    </actuator>
  </transmission>

  <transmission name="transm_r_l_2">
    <type>transmission_interface/SimpleTransmission</type>
    <joint name="j_2_r_l">
      <hardwareInterface>hardware_interface/EffortJointInterface</hardwareInterface>  
    </joint>
    <actuator name="m_r_l_2">
      <hardwareInterface>hardware_interface/EffortJointInterface</hardwareInterface>
      <mechanicalReduction>1</mechanicalReduction>
    </actuator>
  </transmission>

  <transmission name="transm_r_l_3">
    <type>transmission_interface/SimpleTransmission</type>
    <joint name="j_3_r_l">
      <hardwareInterface>hardware_interface/EffortJointInterface</hardwareInterface>    
    </joint>
    <actuator name="m_r_l_3">
      <hardwareInterface>hardware_interface/EffortJointInterface</hardwareInterface>
      <mechanicalReduction>1</mechanicalReduction>
    </actuator>
  </transmission> 

  <transmission name="transm_r_r_1">
    <type>transmission_interface/SimpleTransmission</type>
    <joint name="j_1_r_r">
      <hardwareInterface>hardware_interface/EffortJointInterface</hardwareInterface>    
    </joint>
    <actuator name="m_r_r_1">
      <hardwareInterface>hardware_interface/EffortJointInterface</hardwareInterface>
      <mechanicalReduction>1</mechanicalReduction>
    </actuator>
  </transmission>

  <transmission name="transm_r_r_2">
    <type>transmission_interface/SimpleTransmission</type>
    <joint name="j_2_r_r">
      <hardwareInterface>hardware_interface/EffortJointInterface</hardwareInterface>    
    </joint>
    <actuator name="m_r_r_2">
      <hardwareInterface>hardware_interface/EffortJointInterface</hardwareInterface>
      <mechanicalReduction>1</mechanicalReduction>
    </actuator>
  </transmission>

  <transmission name="transm_r_r_3">
    <type>transmission_interface/SimpleTransmission</type>
    <joint name="j_3_r_r">
      <hardwareInterface>hardware_interface/EffortJointInterface</hardwareInterface>    
    </joint>
    <actuator name="m_r_r_3">
      <hardwareInterface>hardware_interface/EffortJointInterface</hardwareInterface>
      <mechanicalReduction>1</mechanicalReduction>
    </actuator>
  </transmission>

<!--   <gazebo reference="head">
    <material>Gazebo/Orange</material>
  </gazebo> -->

<!--   <gazebo reference="tarsus_f_l">    
    <mu1>10000</mu1>
    <mu2>10000</mu2>
  </gazebo>

  <gazebo reference="tarsus_f_r">    
    <mu1>10000</mu1>
    <mu2>10000</mu2>
  </gazebo>

  <gazebo reference="tarsus_m_l">    
    <mu1>10000</mu1>
    <mu2>10000</mu2>
  </gazebo>

  <gazebo reference="tarsus_m_r">    
    <mu1>10000</mu1>
    <mu2>10000</mu2>
  </gazebo>

  <gazebo reference="tarsus_r_r">    
    <mu1>10000</mu1>
    <mu2>10000</mu2>
  </gazebo>

  <gazebo reference="tarsus_r_l">    
    <mu1>10000</mu1>
    <mu2>10000</mu2>
  </gazebo>  -->

  <material name="black">
    <color rgba="0.0 0.0 0.0 1.0"/>
  </material>

  <material name="grey">
    <color rgba="0.2 0.2 0.2 1.0"/>
  </material>

  <material name="brown">
    <color rgba="${222/255} ${207/255} ${195/255} 1.0"/>
  </material>

  <gazebo>
    <plugin filename="libgazebo_ros_control.so" name="gazebo_ros_control">
      <robotNamespace>/ant</robotNamespace>
    </plugin>
  </gazebo>
  
</robot>
